Workbook

Sheet Yeterlilik
J1: PROSES VE MAKİNE YETERLİLİĞİ · PROSES | AK1: Dok. No | AN1: FR24
AK2: Y. Tarihi | AN2: 02.01.2023
AK3: Rev. No | AN3: 01 / 25.08.2026
AK4: Sayfa | AN4: 1 / 1
A7: ÖLÇÜM DEĞERLERİ (125 adet · Kumpas) | J7: TANIMLAMA
A8: i | B8: xi | C8: i | D8: xi | E8: i | F8: xi | J8: Ürün
A9: 1 | C9: 51 | E9: 101 | J9: Müşteri
A10: 2 | C10: 52 | E10: 102 | J10: Teknik resim
A11: 3 | C11: 53 | E11: 103 | J11: Karakteristik
A12: 4 | C12: 54 | E12: 104 | J12: Ölçüm aleti
A13: 5 | C13: 55 | E13: 105 | J13: Sorumlu
A14: 6 | C14: 56 | E14: 106 | J14: Tarih
A15: 7 | C15: 57 | E15: 107 | J15: Birim
A16: 8 | C16: 58 | E16: 108
A17: 9 | C17: 59 | E17: 109 | J17: ŞARTNAME
A18: 10 | C18: 60 | E18: 110 | J18: Nominal değer
A19: 11 | C19: 61 | E19: 111 | J19: Alt limit (LSL)
A20: 12 | C20: 62 | E20: 112 | J20: Üst limit (USL)
A21: 13 | C21: 63 | E21: 113 | J21: Tolerans | N21: =N20-N19
A22: 14 | C22: 64 | E22: 114
A23: 15 | C23: 65 | E23: 115 | J23: İSTATİSTİK (canlı formül)
A24: 16 | C24: 66 | E24: 116 | J24: Örnek sayısı n | N24: =COUNT(B9:B58,D9:D58,F9:F33)
A25: 17 | C25: 67 | E25: 117 | J25: Ortalama | N25: =IF($N$24=0,"",AVERAGE(B9:B58,D9:D58,F9:F33))
A26: 18 | C26: 68 | E26: 118 | J26: Medyan | N26: =IF($N$24=0,"",MEDIAN(B9:B58,D9:D58,F9:F33))
A27: 19 | C27: 69 | E27: 119 | J27: En küçük | N27: =IF($N$24=0,"",MIN(B9:B58,D9:D58,F9:F33))
A28: 20 | C28: 70 | E28: 120 | J28: En büyük | N28: =IF($N$24=0,"",MAX(B9:B58,D9:D58,F9:F33))
A29: 21 | C29: 71 | E29: 121 | J29: Yayılım R | N29: =IF($N$24=0,"",MAX(B9:B58,D9:D58,F9:F33)-MIN(B9:B58,D9:D58,F9:F33))
A30: 22 | C30: 72 | E30: 122 | J30: Std. sapma s | N30: =IF($N$24<2,"",STDEV(B9:B58,D9:D58,F9:F33))
A31: 23 | C31: 73 | E31: 123 | J31: Anderson-Darling | N31: =IF(veri!$AK$1="","yetersiz veri (n<8)","A² = "&ROUND(veri!$AK$1,3)&" · kritik %5 = 0.752")
A32: 24 | C32: 74 | E32: 124 | J32: Dağılım | N32: =IF(veri!$AK$1="","—",IF(veri!$AK$1<=0.752,"normal","normal DEĞİL"))
A33: 25 | C33: 75 | E33: 125
A34: 26 | C34: 76 | J34: YETERLİLİK (dağılıma göre düzeltilmiş — rapor değeri)
A35: 27 | C35: 77 | J35: Cpkl (alt yan) | N35: =IF($N$24=0,"",IF($N$30=0,"",IF($N$32="normal",($N$25-$N$19)/(3*$N$30),IF((MEDIAN(veri!$B$2:$B$126)-PERCENTILE(veri!$B$2:$B$126,0.00135))<=0,"",(MEDIAN(veri!$B$2:$B$126)-$N$19)/(MEDIAN(veri!$B$2:$B$126)-PERCENTILE(veri!$B$2:$B$126,0.00135))))))
A36: 28 | C36: 78 | J36: Cpku (üst yan) | N36: =IF($N$24=0,"",IF($N$30=0,"",IF($N$32="normal",($N$20-$N$25)/(3*$N$30),IF((PERCENTILE(veri!$B$2:$B$126,0.99865)-MEDIAN(veri!$B$2:$B$126))<=0,"",($N$20-MEDIAN(veri!$B$2:$B$126))/(PERCENTILE(veri!$B$2:$B$126,0.99865)-MEDIAN(veri!$B$2:$B$126))))))
A37: 29 | C37: 79 | J37: Cp | N37: =IF($N$24=0,"",IF($N$30=0,"",IF($N$32="normal",($N$20-$N$19)/(6*$N$30),IF((PERCENTILE(veri!$B$2:$B$126,0.99865)-PERCENTILE(veri!$B$2:$B$126,0.00135))<=0,"",($N$20-$N$19)/(PERCENTILE(veri!$B$2:$B$126,0.99865)-PERCENTILE(veri!$B$2:$B$126,0.00135))))))
A38: 30 | C38: 80 | J38: Cpk | N38: =IF(AND($N$35="",$N$36=""),"",IF($N$35="",$N$36,IF($N$36="",$N$35,MIN($N$35,$N$36))))
A39: 31 | C39: 81 | J39: Pp | N39: =$N$37
A40: 32 | C40: 82 | J40: Ppk | N40: =$N$38
A41: 33 | C41: 83 | J41: Yöntem | N41: =IF($N$32="normal","normal dağılım (Cp/Cpk = 6s)","yüzdelik (ISO 22514-2) — dağılım normal değil")
A42: 34 | C42: 84
...

Sheet veri
AD1: =IF(Yeterlilik!$N$24=0,Yeterlilik!$N$19,MIN(MIN($B$2:$B$126),Yeterlilik!$N$19)) | AE1: =IF(Yeterlilik!$N$24=0,Yeterlilik!$N$20,MAX(MAX($B$2:$B$126),Yeterlilik!$N$20)) | AF1: =($AE$1-$AD$1)/15 | AK1: =IF(Yeterlilik!$N$24<8,"",(-Yeterlilik!$N$24-SUM($AI$2:$AI$126)/Yeterlilik!$N$24)*(1+0.75/Yeterlilik!$N$24+2.25/Yeterlilik!$N$24^2)) | AM1: =(Yeterlilik!$N$19+Yeterlilik!$N$20)/2
A2: =IF(B2="","",1) | B2: =IF(Yeterlilik!$B$9="","",Yeterlilik!$B$9) | D2: =1 | E2: =Yeterlilik!$N$19 | F2: =Yeterlilik!$N$20 | G2: =Yeterlilik!$N$25 | H2: =Yeterlilik!$N$25-3*Yeterlilik!$N$30 | I2: =Yeterlilik!$N$25+3*Yeterlilik!$N$30 | K2: =$AD$1+0*$AF$1 | L2: =0 | N2: =$AD$1+0*(($AE$1-$AD$1)/119) | O2: =IF(Yeterlilik!$N$30=0,0,Yeterlilik!$N$24*$AF$1*NORMDIST(N2,Yeterlilik!$N$25,Yeterlilik!$N$30,FALSE)) | Q2: =0 | R2: =Yeterlilik!$N$19 | S2: =Yeterlilik!$N$20 | T2: =Yeterlilik!$N$18 | U2: =Yeterlilik!$N$25-3*Yeterlilik!$N$30 | V2: =Yeterlilik!$N$25+3*Yeterlilik!$N$30 | X2: =IF(1>Yeterlilik!$N$24,"",SMALL($B$2:$B$126,1)) | Y2: =IF(X2="","",NORMSINV((1-0.375)/(Yeterlilik!$N$24+0.25))) | AA2: =Yeterlilik!$N$25-3*Yeterlilik!$N$30 | AB2: =-3 | AH2: =IF(X2="","",NORMSDIST((X2-Yeterlilik!$N$25)/Yeterlilik!$N$30)) | AI2: =IF(OR(X2="",AH2<=0,AH2>=1),0,(1*2-1)*(LN(AH2)+LN(1-INDEX($AH$2:$AH$126,Yeterlilik!$N$24+1-1)))) | AM2: =IF(B2="",NA(),B2-$AM$1) | AN2: =E2-$AM$1 | AO2: =F2-$AM$1 | AP2: =G2-$AM$1 | AQ2: =H2-$AM$1 | AR2: =I2-$AM$1 | AS2: =K2-$AM$1 | AT2: =N2-$AM$1 | AU2: =R2-$AM$1 | AV2: =S2-$AM$1 | AW2: =IF(Yeterlilik!$N$18="",NA(),T2-$AM$1) | AX2: =U2-$AM$1 | AY2: =V2-$AM$1 | AZ2: =IF(X2="",NA(),X2-$AM$1) | BA2: =AA2-$AM$1 | BB2: =IF(Y2="",NA(),Y2)
A3: =IF(B3="","",2) | B3: =IF(Yeterlilik!$B$10="","",Yeterlilik!$B$10) | D3: =125 | E3: =Yeterlilik!$N$19 | F3: =Yeterlilik!$N$20 | G3: =Yeterlilik!$N$25 | H3: =Yeterlilik!$N$25-3*Yeterlilik!$N$30 | I3: =Yeterlilik!$N$25+3*Yeterlilik!$N$30 | K3: =$AD$1+0*$AF$1 | L3: =COUNTIFS($B$2:$B$126,">="&$AD$1+0*$AF$1,$B$2:$B$126,"<"&$AD$1+1*$AF$1) | N3: =$AD$1+1*(($AE$1-$AD$1)/119) | O3: =IF(Yeterlilik!$N$30=0,0,Yeterlilik!$N$24*$AF$1*NORMDIST(N3,Yeterlilik!$N$25,Yeterlilik!$N$30,FALSE)) | Q3: =_xlfn.AGGREGATE(4,6,$L$2:$L$47)*1.1 | R3: =Yeterlilik!$N$19 | S3: =Yeterlilik!$N$20 | T3: =Yeterlilik!$N$18 | U3: =Yeterlilik!$N$25-3*Yeterlilik!$N$30 | V3: =Yeterlilik!$N$25+3*Yeterlilik!$N$30 | X3: =IF(2>Yeterlilik!$N$24,"",SMALL($B$2:$B$126,2)) | Y3: =IF(X3="","",NORMSINV((2-0.375)/(Yeterlilik!$N$24+0.25))) | AA3: =Yeterlilik!$N$25+3*Yeterlilik!$N$30 | AB3: =3 | AH3: =IF(X3="","",NORMSDIST((X3-Yeterlilik!$N$25)/Yeterlilik!$N$30)) | AI3: =IF(OR(X3="",AH3<=0,AH3>=1),0,(2*2-1)*(LN(AH3)+LN(1-INDEX($AH$2:$AH$126,Yeterlilik!$N$24+1-2)))) | AM3: =IF(B3="",NA(),B3-$AM$1) | AN3: =E3-$AM$1 | AO3: =F3-$AM$1 | AP3: =G3-$AM$1 | AQ3: =H3-$AM$1 | AR3: =I3-$AM$1 | AS3: =K3-$AM$1 | AT3: =N3-$AM$1 | AU3: =R3-$AM$1 | AV3: =S3-$AM$1 | AW3: =IF(Yeterlilik!$N$18="",NA(),T3-$AM$1) | AX3: =U3-$AM$1 | AY3: =V3-$AM$1 | AZ3: =IF(X3="",NA(),X3-$AM$1) | BA3: =AA3-$AM$1 | BB3: =IF(Y3="",NA(),Y3)
A4: =IF(B4="","",3) | B4: =IF(Yeterlilik!$B$11="","",Yeterlilik!$B$11) | K4: =$AD$1+1*$AF$1 | L4: =COUNTIFS($B$2:$B$126,">="&$AD$1+0*$AF$1,$B$2:$B$126,"<"&$AD$1+1*$AF$1) | N4: =$AD$1+2*(($AE$1-$AD$1)/119) | O4: =IF(Yeterlilik!$N$30=0,0,Yeterlilik!$N$24*$AF$1*NORMDIST(N4,Yeterlilik!$N$25,Yeterlilik!$N$30,FALSE)) | X4: =IF(3>Yeterlilik!$N$24,"",SMALL($B$2:$B$126,3)) | Y4: =IF(X4="","",NORMSINV((3-0.375)/(Yeterlilik!$N$24+0.25))) | AH4: =IF(X4="","",NORMSDIST((X4-Yeterlilik!$N$25)/Yeterlilik!$N$30)) | AI4: =IF(OR(X4="",AH4<=0,AH4>=1),0,(3*2-1)*(LN(AH4)+LN(1-INDEX($AH$2:$AH$126,Yeterlilik!$N$24+1-3)))) | AM4: =IF(B4="",NA(),B4-$AM$1) | AS4: =K4-$AM$1 | AT4: =N4-$AM$1 | AZ4: =IF(X4="",NA(),X4-$AM$1) | BB4: =IF(Y4="",NA(),Y4)
A5: =IF(B5="","",4) | B5: =IF(Yeterlilik!$B$12="","",Yeterlilik!$B$12) | K5: =$AD$1+1*$AF$1 | L5: =COUNTIFS($B$2:$B$126,">="&$AD$1+1*$AF$1,$B$2:$B$126,"<"&$AD$1+2*$AF$1) | N5: =$AD$1+3*(($AE$1-$AD$1)/119) | O5: =IF(Yeterlilik!$N$30=0,0,Yeterlilik!$N$24*$AF$1*NORMDIST(N5,Yeterlilik!$N$25,Yeterlilik!$N$30,FALSE)) | X5: =IF(4>Yeterlilik!$N$24,"",SMALL($B$2:$B$126,4)) | Y5: =IF(X5="","",NORMSINV((4-0.375)/(Yeterlilik!$N$24+0.25))) | AH5: =IF(X5="","",NORMSDIST((X5-Yeterlilik!$N$25)/Yeterlilik!$N$30)) | AI5: =IF(OR(X5="",AH5<=0,AH5>=1),0,(4*2-1)*(LN(AH5)+LN(1-INDEX($AH$2:$AH$126,Yeterlilik!$N$24+1-4)))) | AM5: =IF(B5="",NA(),B5-$AM$1) | AS5: =K5-$AM$1 | AT5: =N5-$AM$1 | AZ5: =IF(X5="",NA(),X5-$AM$1) | BB5: =IF(Y5="",NA(),Y5)
A6: =IF(B6="","",5) | B6: =IF(Yeterlilik!$B$13="","",Yeterlilik!$B$13) | K6: =$AD$1+2*$AF$1 | L6: =COUNTIFS($B$2:$B$126,">="&$AD$1+1*$AF$1,$B$2:$B$126,"<"&$AD$1+2*$AF$1) | N6: =$AD$1+4*(($AE$1-$AD$1)/119) | O6: =IF(Yeterlilik!$N$30=0,0,Yeterlilik!$N$24*$AF$1*NORMDIST(N6,Yeterlilik!$N$25,Yeterlilik!$N$30,FALSE)) | X6: =IF(5>Yeterlilik!$N$24,"",SMALL($B$2:$B$126,5)) | Y6: =IF(X6="","",NORMSINV((5-0.375)/(Yeterlilik!$N$24+0.25))) | AH6: =IF(X6="","",NORMSDIST((X6-Yeterlilik!$N$25)/Yeterlilik!$N$30)) | AI6: =IF(OR(X6="",AH6<=0,AH6>=1),0,(5*2-1)*(LN(AH6)+LN(1-INDEX($AH$2:$AH$126,Yeterlilik!$N$24+1-5)))) | AM6: =IF(B6="",NA(),B6-$AM$1) | AS6: =K6-$AM$1 | AT6: =N6-$AM$1 | AZ6: =IF(X6="",NA(),X6-$AM$1) | BB6: =IF(Y6="",NA(),Y6)
A7: =IF(B7="","",6) | B7: =IF(Yeterlilik!$B$14="","",Yeterlilik!$B$14) | K7: =$AD$1+2*$AF$1 | L7: =COUNTIFS($B$2:$B$126,">="&$AD$1+2*$AF$1,$B$2:$B$126,"<"&$AD$1+3*$AF$1) | N7: =$AD$1+5*(($AE$1-$AD$1)/119) | O7: =IF(Yeterlilik!$N$30=0,0,Yeterlilik!$N$24*$AF$1*NORMDIST(N7,Yeterlilik!$N$25,Yeterlilik!$N$30,FALSE)) | X7: =IF(6>Yeterlilik!$N$24,"",SMALL($B$2:$B$126,6)) | Y7: =IF(X7="","",NORMSINV((6-0.375)/(Yeterlilik!$N$24+0.25))) | AH7: =IF(X7="","",NORMSDIST((X7-Yeterlilik!$N$25)/Yeterlilik!$N$30)) | AI7: =IF(OR(X7="",AH7<=0,AH7>=1),0,(6*2-1)*(LN(AH7)+LN(1-INDEX($AH$2:$AH$126,Yeterlilik!$N$24+1-6)))) | AM7: =IF(B7="",NA(),B7-$AM$1) | AS7: =K7-$AM$1 | AT7: =N7-$AM$1 | AZ7: =IF(X7="",NA(),X7-$AM$1) | BB7: =IF(Y7="",NA(),Y7)
A8: =IF(B8="","",7) | B8: =IF(Yeterlilik!$B$15="","",Yeterlilik!$B$15) | K8: =$AD$1+3*$AF$1 | L8: =COUNTIFS($B$2:$B$126,">="&$AD$1+2*$AF$1,$B$2:$B$126,"<"&$AD$1+3*$AF$1) | N8: =$AD$1+6*(($AE$1-$AD$1)/119) | O8: =IF(Yeterlilik!$N$30=0,0,Yeterlilik!$N$24*$AF$1*NORMDIST(N8,Yeterlilik!$N$25,Yeterlilik!$N$30,FALSE)) | X8: =IF(7>Yeterlilik!$N$24,"",SMALL($B$2:$B$126,7)) | Y8: =IF(X8="","",NORMSINV((7-0.375)/(Yeterlilik!$N$24+0.25))) | AH8: =IF(X8="","",NORMSDIST((X8-Yeterlilik!$N$25)/Yeterlilik!$N$30)) | AI8: =IF(OR(X8="",AH8<=0,AH8>=1),0,(7*2-1)*(LN(AH8)+LN(1-INDEX($AH$2:$AH$126,Yeterlilik!$N$24+1-7)))) | AM8: =IF(B8="",NA(),B8-$AM$1) | AS8: =K8-$AM$1 | AT8: =N8-$AM$1 | AZ8: =IF(X8="",NA(),X8-$AM$1) | BB8: =IF(Y8="",NA(),Y8)
A9: =IF(B9="","",8) | B9: =IF(Yeterlilik!$B$16="","",Yeterlilik!$B$16) | K9: =$AD$1+3*$AF$1 | L9: =COUNTIFS($B$2:$B$126,">="&$AD$1+3*$AF$1,$B$2:$B$126,"<"&$AD$1+4*$AF$1) | N9: =$AD$1+7*(($AE$1-$AD$1)/119) | O9: =IF(Yeterlilik!$N$30=0,0,Yeterlilik!$N$24*$AF$1*NORMDIST(N9,Yeterlilik!$N$25,Yeterlilik!$N$30,FALSE)) | X9: =IF(8>Yeterlilik!$N$24,"",SMALL($B$2:$B$126,8)) | Y9: =IF(X9="","",NORMSINV((8-0.375)/(Yeterlilik!$N$24+0.25))) | AH9: =IF(X9="","",NORMSDIST((X9-Yeterlilik!$N$25)/Yeterlilik!$N$30)) | AI9: =IF(OR(X9="",AH9<=0,AH9>=1),0,(8*2-1)*(LN(AH9)+LN(1-INDEX($AH$2:$AH$126,Yeterlilik!$N$24+1-8)))) | AM9: =IF(B9="",NA(),B9-$AM$1) | AS9: =K9-$AM$1 | AT9: =N9-$AM$1 | AZ9: =IF(X9="",NA(),X9-$AM$1) | BB9: =IF(Y9="",NA(),Y9)
A10: =IF(B10="","",9) | B10: =IF(Yeterlilik!$B$17="","",Yeterlilik!$B$17) | K10: =$AD$1+4*$AF$1 | L10: =COUNTIFS($B$2:$B$126,">="&$AD$1+3*$AF$1,$B$2:$B$126,"<"&$AD$1+4*$AF$1) | N10: =$AD$1+8*(($AE$1-$AD$1)/119) | O10: =IF(Yeterlilik!$N$30=0,0,Yeterlilik!$N$24*$AF$1*NORMDIST(N10,Yeterlilik!$N$25,Yeterlilik!$N$30,FALSE)) | X10: =IF(9>Yeterlilik!$N$24,"",SMALL($B$2:$B$126,9)) | Y10: =IF(X10="","",NORMSINV((9-0.375)/(Yeterlilik!$N$24+0.25))) | AH10: =IF(X10="","",NORMSDIST((X10-Yeterlilik!$N$25)/Yeterlilik!$N$30)) | AI10: =IF(OR(X10="",AH10<=0,AH10>=1),0,(9*2-1)*(LN(AH10)+LN(1-INDEX($AH$2:$AH$126,Yeterlilik!$N$24+1-9)))) | AM10: =IF(B10="",NA(),B10-$AM$1) | AS10: =K10-$AM$1 | AT10: =N10-$AM$1 | AZ10: =IF(X10="",NA(),X10-$AM$1) | BB10: =IF(Y10="",NA(),Y10)
A11: =IF(B11="","",10) | B11: =IF(Yeterlilik!$B$18="","",Yeterlilik!$B$18) | K11: =$AD$1+4*$AF$1 | L11: =COUNTIFS($B$2:$B$126,">="&$AD$1+4*$AF$1,$B$2:$B$126,"<"&$AD$1+5*$AF$1) | N11: =$AD$1+9*(($AE$1-$AD$1)/119) | O11: =IF(Yeterlilik!$N$30=0,0,Yeterlilik!$N$24*$AF$1*NORMDIST(N11,Yeterlilik!$N$25,Yeterlilik!$N$30,FALSE)) | X11: =IF(10>Yeterlilik!$N$24,"",SMALL($B$2:$B$126,10)) | Y11: =IF(X11="","",NORMSINV((10-0.375)/(Yeterlilik!$N$24+0.25))) | AH11: =IF(X11="","",NORMSDIST((X11-Yeterlilik!$N$25)/Yeterlilik!$N$30)) | AI11: =IF(OR(X11="",AH11<=0,AH11>=1),0,(10*2-1)*(LN(AH11)+LN(1-INDEX($AH$2:$AH$126,Yeterlilik!$N$24+1-10)))) | AM11: =IF(B11="",NA(),B11-$AM$1) | AS11: =K11-$AM$1 | AT11: =N11-$AM$1 | AZ11: =IF(X11="",NA(),X11-$AM$1) | BB11: =IF(Y11="",NA(),Y11)
A12: =IF(B12="","",11) | B12: =IF(Yeterlilik!$B$19="","",Yeterlilik!$B$19) | K12: =$AD$1+5*$AF$1 | L12: =COUNTIFS($B$2:$B$126,">="&$AD$1+4*$AF$1,$B$2:$B$126,"<"&$AD$1+5*$AF$1) | N12: =$AD$1+10*(($AE$1-$AD$1)/119) | O12: =IF(Yeterlilik!$N$30=0,0,Yeterlilik!$N$24*$AF$1*NORMDIST(N12,Yeterlilik!$N$25,Yeterlilik!$N$30,FALSE)) | X12: =IF(11>Yeterlilik!$N$24,"",SMALL($B$2:$B$126,11)) | Y12: =IF(X12="","",NORMSINV((11-0.375)/(Yeterlilik!$N$24+0.25))) | AH12: =IF(X12="","",NORMSDIST((X12-Yeterlilik!$N$25)/Yeterlilik!$N$30)) | AI12: =IF(OR(X12="",AH12<=0,AH12>=1),0,(11*2-1)*(LN(AH12)+LN(1-INDEX($AH$2:$AH$126,Yeterlilik!$N$24+1-11)))) | AM12: =IF(B12="",NA(),B12-$AM$1) | AS12: =K12-$AM$1 | AT12: =N12-$AM$1 | AZ12: =IF(X12="",NA(),X12-$AM$1) | BB12: =IF(Y12="",NA(),Y12)
A13: =IF(B13="","",12) | B13: =IF(Yeterlilik!$B$20="","",Yeterlilik!$B$20) | K13: =$AD$1+5*$AF$1 | L13: =COUNTIFS($B$2:$B$126,">="&$AD$1+5*$AF$1,$B$2:$B$126,"<"&$AD$1+6*$AF$1) | N13: =$AD$1+11*(($AE$1-$AD$1)/119) | O13: =IF(Yeterlilik!$N$30=0,0,Yeterlilik!$N$24*$AF$1*NORMDIST(N13,Yeterlilik!$N$25,Yeterlilik!$N$30,FALSE)) | X13: =IF(12>Yeterlilik!$N$24,"",SMALL($B$2:$B$126,12)) | Y13: =IF(X13="","",NORMSINV((12-0.375)/(Yeterlilik!$N$24+0.25))) | AH13: =IF(X13="","",NORMSDIST((X13-Yeterlilik!$N$25)/Yeterlilik!$N$30)) | AI13: =IF(OR(X13="",AH13<=0,AH13>=1),0,(12*2-1)*(LN(AH13)+LN(1-INDEX($AH$2:$AH$126,Yeterlilik!$N$24+1-12)))) | AM13: =IF(B13="",NA(),B13-$AM$1) | AS13: =K13-$AM$1 | AT13: =N13-$AM$1 | AZ13: =IF(X13="",NA(),X13-$AM$1) | BB13: =IF(Y13="",NA(),Y13)
A14: =IF(B14="","",13) | B14: =IF(Yeterlilik!$B$21="","",Yeterlilik!$B$21) | K14: =$AD$1+6*$AF$1 | L14: =COUNTIFS($B$2:$B$126,">="&$AD$1+5*$AF$1,$B$2:$B$126,"<"&$AD$1+6*$AF$1) | N14: =$AD$1+12*(($AE$1-$AD$1)/119) | O14: =IF(Yeterlilik!$N$30=0,0,Yeterlilik!$N$24*$AF$1*NORMDIST(N14,Yeterlilik!$N$25,Yeterlilik!$N$30,FALSE)) | X14: =IF(13>Yeterlilik!$N$24,"",SMALL($B$2:$B$126,13)) | Y14: =IF(X14="","",NORMSINV((13-0.375)/(Yeterlilik!$N$24+0.25))) | AH14: =IF(X14="","",NORMSDIST((X14-Yeterlilik!$N$25)/Yeterlilik!$N$30)) | AI14: =IF(OR(X14="",AH14<=0,AH14>=1),0,(13*2-1)*(LN(AH14)+LN(1-INDEX($AH$2:$AH$126,Yeterlilik!$N$24+1-13)))) | AM14: =IF(B14="",NA(),B14-$AM$1) | AS14: =K14-$AM$1 | AT14: =N14-$AM$1 | AZ14: =IF(X14="",NA(),X14-$AM$1) | BB14: =IF(Y14="",NA(),Y14)
A15: =IF(B15="","",14) | B15: =IF(Yeterlilik!$B$22="","",Yeterlilik!$B$22) | K15: =$AD$1+6*$AF$1 | L15: =COUNTIFS($B$2:$B$126,">="&$AD$1+6*$AF$1,$B$2:$B$126,"<"&$AD$1+7*$AF$1) | N15: =$AD$1+13*(($AE$1-$AD$1)/119) | O15: =IF(Yeterlilik!$N$30=0,0,Yeterlilik!$N$24*$AF$1*NORMDIST(N15,Yeterlilik!$N$25,Yeterlilik!$N$30,FALSE)) | X15: =IF(14>Yeterlilik!$N$24,"",SMALL($B$2:$B$126,14)) | Y15: =IF(X15="","",NORMSINV((14-0.375)/(Yeterlilik!$N$24+0.25))) | AH15: =IF(X15="","",NORMSDIST((X15-Yeterlilik!$N$25)/Yeterlilik!$N$30)) | AI15: =IF(OR(X15="",AH15<=0,AH15>=1),0,(14*2-1)*(LN(AH15)+LN(1-INDEX($AH$2:$AH$126,Yeterlilik!$N$24+1-14)))) | AM15: =IF(B15="",NA(),B15-$AM$1) | AS15: =K15-$AM$1 | AT15: =N15-$AM$1 | AZ15: =IF(X15="",NA(),X15-$AM$1) | BB15: =IF(Y15="",NA(),Y15)
A16: =IF(B16="","",15) | B16: =IF(Yeterlilik!$B$23="","",Yeterlilik!$B$23) | K16: =$AD$1+7*$AF$1 | L16: =COUNTIFS($B$2:$B$126,">="&$AD$1+6*$AF$1,$B$2:$B$126,"<"&$AD$1+7*$AF$1) | N16: =$AD$1+14*(($AE$1-$AD$1)/119) | O16: =IF(Yeterlilik!$N$30=0,0,Yeterlilik!$N$24*$AF$1*NORMDIST(N16,Yeterlilik!$N$25,Yeterlilik!$N$30,FALSE)) | X16: =IF(15>Yeterlilik!$N$24,"",SMALL($B$2:$B$126,15)) | Y16: =IF(X16="","",NORMSINV((15-0.375)/(Yeterlilik!$N$24+0.25))) | AH16: =IF(X16="","",NORMSDIST((X16-Yeterlilik!$N$25)/Yeterlilik!$N$30)) | AI16: =IF(OR(X16="",AH16<=0,AH16>=1),0,(15*2-1)*(LN(AH16)+LN(1-INDEX($AH$2:$AH$126,Yeterlilik!$N$24+1-15)))) | AM16: =IF(B16="",NA(),B16-$AM$1) | AS16: =K16-$AM$1 | AT16: =N16-$AM$1 | AZ16: =IF(X16="",NA(),X16-$AM$1) | BB16: =IF(Y16="",NA(),Y16)
A17: =IF(B17="","",16) | B17: =IF(Yeterlilik!$B$24="","",Yeterlilik!$B$24) | K17: =$AD$1+7*$AF$1 | L17: =COUNTIFS($B$2:$B$126,">="&$AD$1+7*$AF$1,$B$2:$B$126,"<"&$AD$1+8*$AF$1) | N17: =$AD$1+15*(($AE$1-$AD$1)/119) | O17: =IF(Yeterlilik!$N$30=0,0,Yeterlilik!$N$24*$AF$1*NORMDIST(N17,Yeterlilik!$N$25,Yeterlilik!$N$30,FALSE)) | X17: =IF(16>Yeterlilik!$N$24,"",SMALL($B$2:$B$126,16)) | Y17: =IF(X17="","",NORMSINV((16-0.375)/(Yeterlilik!$N$24+0.25))) | AH17: =IF(X17="","",NORMSDIST((X17-Yeterlilik!$N$25)/Yeterlilik!$N$30)) | AI17: =IF(OR(X17="",AH17<=0,AH17>=1),0,(16*2-1)*(LN(AH17)+LN(1-INDEX($AH$2:$AH$126,Yeterlilik!$N$24+1-16)))) | AM17: =IF(B17="",NA(),B17-$AM$1) | AS17: =K17-$AM$1 | AT17: =N17-$AM$1 | AZ17: =IF(X17="",NA(),X17-$AM$1) | BB17: =IF(Y17="",NA(),Y17)
A18: =IF(B18="","",17) | B18: =IF(Yeterlilik!$B$25="","",Yeterlilik!$B$25) | K18: =$AD$1+8*$AF$1 | L18: =COUNTIFS($B$2:$B$126,">="&$AD$1+7*$AF$1,$B$2:$B$126,"<"&$AD$1+8*$AF$1) | N18: =$AD$1+16*(($AE$1-$AD$1)/119) | O18: =IF(Yeterlilik!$N$30=0,0,Yeterlilik!$N$24*$AF$1*NORMDIST(N18,Yeterlilik!$N$25,Yeterlilik!$N$30,FALSE)) | X18: =IF(17>Yeterlilik!$N$24,"",SMALL($B$2:$B$126,17)) | Y18: =IF(X18="","",NORMSINV((17-0.375)/(Yeterlilik!$N$24+0.25))) | AH18: =IF(X18="","",NORMSDIST((X18-Yeterlilik!$N$25)/Yeterlilik!$N$30)) | AI18: =IF(OR(X18="",AH18<=0,AH18>=1),0,(17*2-1)*(LN(AH18)+LN(1-INDEX($AH$2:$AH$126,Yeterlilik!$N$24+1-17)))) | AM18: =IF(B18="",NA(),B18-$AM$1) | AS18: =K18-$AM$1 | AT18: =N18-$AM$1 | AZ18: =IF(X18="",NA(),X18-$AM$1) | BB18: =IF(Y18="",NA(),Y18)
A19: =IF(B19="","",18) | B19: =IF(Yeterlilik!$B$26="","",Yeterlilik!$B$26) | K19: =$AD$1+8*$AF$1 | L19: =COUNTIFS($B$2:$B$126,">="&$AD$1+8*$AF$1,$B$2:$B$126,"<"&$AD$1+9*$AF$1) | N19: =$AD$1+17*(($AE$1-$AD$1)/119) | O19: =IF(Yeterlilik!$N$30=0,0,Yeterlilik!$N$24*$AF$1*NORMDIST(N19,Yeterlilik!$N$25,Yeterlilik!$N$30,FALSE)) | X19: =IF(18>Yeterlilik!$N$24,"",SMALL($B$2:$B$126,18)) | Y19: =IF(X19="","",NORMSINV((18-0.375)/(Yeterlilik!$N$24+0.25))) | AH19: =IF(X19="","",NORMSDIST((X19-Yeterlilik!$N$25)/Yeterlilik!$N$30)) | AI19: =IF(OR(X19="",AH19<=0,AH19>=1),0,(18*2-1)*(LN(AH19)+LN(1-INDEX($AH$2:$AH$126,Yeterlilik!$N$24+1-18)))) | AM19: =IF(B19="",NA(),B19-$AM$1) | AS19: =K19-$AM$1 | AT19: =N19-$AM$1 | AZ19: =IF(X19="",NA(),X19-$AM$1) | BB19: =IF(Y19="",NA(),Y19)
A20: =IF(B20="","",19) | B20: =IF(Yeterlilik!$B$27="","",Yeterlilik!$B$27) | K20: =$AD$1+9*$AF$1 | L20: =COUNTIFS($B$2:$B$126,">="&$AD$1+8*$AF$1,$B$2:$B$126,"<"&$AD$1+9*$AF$1) | N20: =$AD$1+18*(($AE$1-$AD$1)/119) | O20: =IF(Yeterlilik!$N$30=0,0,Yeterlilik!$N$24*$AF$1*NORMDIST(N20,Yeterlilik!$N$25,Yeterlilik!$N$30,FALSE)) | X20: =IF(19>Yeterlilik!$N$24,"",SMALL($B$2:$B$126,19)) | Y20: =IF(X20="","",NORMSINV((19-0.375)/(Yeterlilik!$N$24+0.25))) | AH20: =IF(X20="","",NORMSDIST((X20-Yeterlilik!$N$25)/Yeterlilik!$N$30)) | AI20: =IF(OR(X20="",AH20<=0,AH20>=1),0,(19*2-1)*(LN(AH20)+LN(1-INDEX($AH$2:$AH$126,Yeterlilik!$N$24+1-19)))) | AM20: =IF(B20="",NA(),B20-$AM$1) | AS20: =K20-$AM$1 | AT20: =N20-$AM$1 | AZ20: =IF(X20="",NA(),X20-$AM$1) | BB20: =IF(Y20="",NA(),Y20)
A21: =IF(B21="","",20) | B21: =IF(Yeterlilik!$B$28="","",Yeterlilik!$B$28) | K21: =$AD$1+9*$AF$1 | L21: =COUNTIFS($B$2:$B$126,">="&$AD$1+9*$AF$1,$B$2:$B$126,"<"&$AD$1+10*$AF$1) | N21: =$AD$1+19*(($AE$1-$AD$1)/119) | O21: =IF(Yeterlilik!$N$30=0,0,Yeterlilik!$N$24*$AF$1*NORMDIST(N21,Yeterlilik!$N$25,Yeterlilik!$N$30,FALSE)) | X21: =IF(20>Yeterlilik!$N$24,"",SMALL($B$2:$B$126,20)) | Y21: =IF(X21="","",NORMSINV((20-0.375)/(Yeterlilik!$N$24+0.25))) | AH21: =IF(X21="","",NORMSDIST((X21-Yeterlilik!$N$25)/Yeterlilik!$N$30)) | AI21: =IF(OR(X21="",AH21<=0,AH21>=1),0,(20*2-1)*(LN(AH21)+LN(1-INDEX($AH$2:$AH$126,Yeterlilik!$N$24+1-20)))) | AM21: =IF(B21="",NA(),B21-$AM$1) | AS21: =K21-$AM$1 | AT21: =N21-$AM$1 | AZ21: =IF(X21="",NA(),X21-$AM$1) | BB21: =IF(Y21="",NA(),Y21)
A22: =IF(B22="","",21) | B22: =IF(Yeterlilik!$B$29="","",Yeterlilik!$B$29) | K22: =$AD$1+10*$AF$1 | L22: =COUNTIFS($B$2:$B$126,">="&$AD$1+9*$AF$1,$B$2:$B$126,"<"&$AD$1+10*$AF$1) | N22: =$AD$1+20*(($AE$1-$AD$1)/119) | O22: =IF(Yeterlilik!$N$30=0,0,Yeterlilik!$N$24*$AF$1*NORMDIST(N22,Yeterlilik!$N$25,Yeterlilik!$N$30,FALSE)) | X22: =IF(21>Yeterlilik!$N$24,"",SMALL($B$2:$B$126,21)) | Y22: =IF(X22="","",NORMSINV((21-0.375)/(Yeterlilik!$N$24+0.25))) | AH22: =IF(X22="","",NORMSDIST((X22-Yeterlilik!$N$25)/Yeterlilik!$N$30)) | AI22: =IF(OR(X22="",AH22<=0,AH22>=1),0,(21*2-1)*(LN(AH22)+LN(1-INDEX($AH$2:$AH$126,Yeterlilik!$N$24+1-21)))) | AM22: =IF(B22="",NA(),B22-$AM$1) | AS22: =K22-$AM$1 | AT22: =N22-$AM$1 | AZ22: =IF(X22="",NA(),X22-$AM$1) | BB22: =IF(Y22="",NA(),Y22)
A23: =IF(B23="","",22) | B23: =IF(Yeterlilik!$B$30="","",Yeterlilik!$B$30) | K23: =$AD$1+10*$AF$1 | L23: =COUNTIFS($B$2:$B$126,">="&$AD$1+10*$AF$1,$B$2:$B$126,"<"&$AD$1+11*$AF$1) | N23: =$AD$1+21*(($AE$1-$AD$1)/119) | O23: =IF(Yeterlilik!$N$30=0,0,Yeterlilik!$N$24*$AF$1*NORMDIST(N23,Yeterlilik!$N$25,Yeterlilik!$N$30,FALSE)) | X23: =IF(22>Yeterlilik!$N$24,"",SMALL($B$2:$B$126,22)) | Y23: =IF(X23="","",NORMSINV((22-0.375)/(Yeterlilik!$N$24+0.25))) | AH23: =IF(X23="","",NORMSDIST((X23-Yeterlilik!$N$25)/Yeterlilik!$N$30)) | AI23: =IF(OR(X23="",AH23<=0,AH23>=1),0,(22*2-1)*(LN(AH23)+LN(1-INDEX($AH$2:$AH$126,Yeterlilik!$N$24+1-22)))) | AM23: =IF(B23="",NA(),B23-$AM$1) | AS23: =K23-$AM$1 | AT23: =N23-$AM$1 | AZ23: =IF(X23="",NA(),X23-$AM$1) | BB23: =IF(Y23="",NA(),Y23)
A24: =IF(B24="","",23) | B24: =IF(Yeterlilik!$B$31="","",Yeterlilik!$B$31) | K24: =$AD$1+11*$AF$1 | L24: =COUNTIFS($B$2:$B$126,">="&$AD$1+10*$AF$1,$B$2:$B$126,"<"&$AD$1+11*$AF$1) | N24: =$AD$1+22*(($AE$1-$AD$1)/119) | O24: =IF(Yeterlilik!$N$30=0,0,Yeterlilik!$N$24*$AF$1*NORMDIST(N24,Yeterlilik!$N$25,Yeterlilik!$N$30,FALSE)) | X24: =IF(23>Yeterlilik!$N$24,"",SMALL($B$2:$B$126,23)) | Y24: =IF(X24="","",NORMSINV((23-0.375)/(Yeterlilik!$N$24+0.25))) | AH24: =IF(X24="","",NORMSDIST((X24-Yeterlilik!$N$25)/Yeterlilik!$N$30)) | AI24: =IF(OR(X24="",AH24<=0,AH24>=1),0,(23*2-1)*(LN(AH24)+LN(1-INDEX($AH$2:$AH$126,Yeterlilik!$N$24+1-23)))) | AM24: =IF(B24="",NA(),B24-$AM$1) | AS24: =K24-$AM$1 | AT24: =N24-$AM$1 | AZ24: =IF(X24="",NA(),X24-$AM$1) | BB24: =IF(Y24="",NA(),Y24)
A25: =IF(B25="","",24) | B25: =IF(Yeterlilik!$B$32="","",Yeterlilik!$B$32) | K25: =$AD$1+11*$AF$1 | L25: =COUNTIFS($B$2:$B$126,">="&$AD$1+11*$AF$1,$B$2:$B$126,"<"&$AD$1+12*$AF$1) | N25: =$AD$1+23*(($AE$1-$AD$1)/119) | O25: =IF(Yeterlilik!$N$30=0,0,Yeterlilik!$N$24*$AF$1*NORMDIST(N25,Yeterlilik!$N$25,Yeterlilik!$N$30,FALSE)) | X25: =IF(24>Yeterlilik!$N$24,"",SMALL($B$2:$B$126,24)) | Y25: =IF(X25="","",NORMSINV((24-0.375)/(Yeterlilik!$N$24+0.25))) | AH25: =IF(X25="","",NORMSDIST((X25-Yeterlilik!$N$25)/Yeterlilik!$N$30)) | AI25: =IF(OR(X25="",AH25<=0,AH25>=1),0,(24*2-1)*(LN(AH25)+LN(1-INDEX($AH$2:$AH$126,Yeterlilik!$N$24+1-24)))) | AM25: =IF(B25="",NA(),B25-$AM$1) | AS25: =K25-$AM$1 | AT25: =N25-$AM$1 | AZ25: =IF(X25="",NA(),X25-$AM$1) | BB25: =IF(Y25="",NA(),Y25)
A26: =IF(B26="","",25) | B26: =IF(Yeterlilik!$B$33="","",Yeterlilik!$B$33) | K26: =$AD$1+12*$AF$1 | L26: =COUNTIFS($B$2:$B$126,">="&$AD$1+11*$AF$1,$B$2:$B$126,"<"&$AD$1+12*$AF$1) | N26: =$AD$1+24*(($AE$1-$AD$1)/119) | O26: =IF(Yeterlilik!$N$30=0,0,Yeterlilik!$N$24*$AF$1*NORMDIST(N26,Yeterlilik!$N$25,Yeterlilik!$N$30,FALSE)) | X26: =IF(25>Yeterlilik!$N$24,"",SMALL($B$2:$B$126,25)) | Y26: =IF(X26="","",NORMSINV((25-0.375)/(Yeterlilik!$N$24+0.25))) | AH26: =IF(X26="","",NORMSDIST((X26-Yeterlilik!$N$25)/Yeterlilik!$N$30)) | AI26: =IF(OR(X26="",AH26<=0,AH26>=1),0,(25*2-1)*(LN(AH26)+LN(1-INDEX($AH$2:$AH$126,Yeterlilik!$N$24+1-25)))) | AM26: =IF(B26="",NA(),B26-$AM$1) | AS26: =K26-$AM$1 | AT26: =N26-$AM$1 | AZ26: =IF(X26="",NA(),X26-$AM$1) | BB26: =IF(Y26="",NA(),Y26)
A27: =IF(B27="","",26) | B27: =IF(Yeterlilik!$B$34="","",Yeterlilik!$B$34) | K27: =$AD$1+12*$AF$1 | L27: =COUNTIFS($B$2:$B$126,">="&$AD$1+12*$AF$1,$B$2:$B$126,"<"&$AD$1+13*$AF$1) | N27: =$AD$1+25*(($AE$1-$AD$1)/119) | O27: =IF(Yeterlilik!$N$30=0,0,Yeterlilik!$N$24*$AF$1*NORMDIST(N27,Yeterlilik!$N$25,Yeterlilik!$N$30,FALSE)) | X27: =IF(26>Yeterlilik!$N$24,"",SMALL($B$2:$B$126,26)) | Y27: =IF(X27="","",NORMSINV((26-0.375)/(Yeterlilik!$N$24+0.25))) | AH27: =IF(X27="","",NORMSDIST((X27-Yeterlilik!$N$25)/Yeterlilik!$N$30)) | AI27: =IF(OR(X27="",AH27<=0,AH27>=1),0,(26*2-1)*(LN(AH27)+LN(1-INDEX($AH$2:$AH$126,Yeterlilik!$N$24+1-26)))) | AM27: =IF(B27="",NA(),B27-$AM$1) | AS27: =K27-$AM$1 | AT27: =N27-$AM$1 | AZ27: =IF(X27="",NA(),X27-$AM$1) | BB27: =IF(Y27="",NA(),Y27)
A28: =IF(B28="","",27) | B28: =IF(Yeterlilik!$B$35="","",Yeterlilik!$B$35) | K28: =$AD$1+13*$AF$1 | L28: =COUNTIFS($B$2:$B$126,">="&$AD$1+12*$AF$1,$B$2:$B$126,"<"&$AD$1+13*$AF$1) | N28: =$AD$1+26*(($AE$1-$AD$1)/119) | O28: =IF(Yeterlilik!$N$30=0,0,Yeterlilik!$N$24*$AF$1*NORMDIST(N28,Yeterlilik!$N$25,Yeterlilik!$N$30,FALSE)) | X28: =IF(27>Yeterlilik!$N$24,"",SMALL($B$2:$B$126,27)) | Y28: =IF(X28="","",NORMSINV((27-0.375)/(Yeterlilik!$N$24+0.25))) | AH28: =IF(X28="","",NORMSDIST((X28-Yeterlilik!$N$25)/Yeterlilik!$N$30)) | AI28: =IF(OR(X28="",AH28<=0,AH28>=1),0,(27*2-1)*(LN(AH28)+LN(1-INDEX($AH$2:$AH$126,Yeterlilik!$N$24+1-27)))) | AM28: =IF(B28="",NA(),B28-$AM$1) | AS28: =K28-$AM$1 | AT28: =N28-$AM$1 | AZ28: =IF(X28="",NA(),X28-$AM$1) | BB28: =IF(Y28="",NA(),Y28)
A29: =IF(B29="","",28) | B29: =IF(Yeterlilik!$B$36="","",Yeterlilik!$B$36) | K29: =$AD$1+13*$AF$1 | L29: =COUNTIFS($B$2:$B$126,">="&$AD$1+13*$AF$1,$B$2:$B$126,"<"&$AD$1+14*$AF$1) | N29: =$AD$1+27*(($AE$1-$AD$1)/119) | O29: =IF(Yeterlilik!$N$30=0,0,Yeterlilik!$N$24*$AF$1*NORMDIST(N29,Yeterlilik!$N$25,Yeterlilik!$N$30,FALSE)) | X29: =IF(28>Yeterlilik!$N$24,"",SMALL($B$2:$B$126,28)) | Y29: =IF(X29="","",NORMSINV((28-0.375)/(Yeterlilik!$N$24+0.25))) | AH29: =IF(X29="","",NORMSDIST((X29-Yeterlilik!$N$25)/Yeterlilik!$N$30)) | AI29: =IF(OR(X29="",AH29<=0,AH29>=1),0,(28*2-1)*(LN(AH29)+LN(1-INDEX($AH$2:$AH$126,Yeterlilik!$N$24+1-28)))) | AM29: =IF(B29="",NA(),B29-$AM$1) | AS29: =K29-$AM$1 | AT29: =N29-$AM$1 | AZ29: =IF(X29="",NA(),X29-$AM$1) | BB29: =IF(Y29="",NA(),Y29)
A30: =IF(B30="","",29) | B30: =IF(Yeterlilik!$B$37="","",Yeterlilik!$B$37) | K30: =$AD$1+14*$AF$1 | L30: =COUNTIFS($B$2:$B$126,">="&$AD$1+13*$AF$1,$B$2:$B$126,"<"&$AD$1+14*$AF$1) | N30: =$AD$1+28*(($AE$1-$AD$1)/119) | O30: =IF(Yeterlilik!$N$30=0,0,Yeterlilik!$N$24*$AF$1*NORMDIST(N30,Yeterlilik!$N$25,Yeterlilik!$N$30,FALSE)) | X30: =IF(29>Yeterlilik!$N$24,"",SMALL($B$2:$B$126,29)) | Y30: =IF(X30="","",NORMSINV((29-0.375)/(Yeterlilik!$N$24+0.25))) | AH30: =IF(X30="","",NORMSDIST((X30-Yeterlilik!$N$25)/Yeterlilik!$N$30)) | AI30: =IF(OR(X30="",AH30<=0,AH30>=1),0,(29*2-1)*(LN(AH30)+LN(1-INDEX($AH$2:$AH$126,Yeterlilik!$N$24+1-29)))) | AM30: =IF(B30="",NA(),B30-$AM$1) | AS30: =K30-$AM$1 | AT30: =N30-$AM$1 | AZ30: =IF(X30="",NA(),X30-$AM$1) | BB30: =IF(Y30="",NA(),Y30)
A31: =IF(B31="","",30) | B31: =IF(Yeterlilik!$B$38="","",Yeterlilik!$B$38) | K31: =$AD$1+14*$AF$1 | L31: =COUNTIFS($B$2:$B$126,">="&$AD$1+14*$AF$1,$B$2:$B$126,"<"&$AD$1+15*$AF$1) | N31: =$AD$1+29*(($AE$1-$AD$1)/119) | O31: =IF(Yeterlilik!$N$30=0,0,Yeterlilik!$N$24*$AF$1*NORMDIST(N31,Yeterlilik!$N$25,Yeterlilik!$N$30,FALSE)) | X31: =IF(30>Yeterlilik!$N$24,"",SMALL($B$2:$B$126,30)) | Y31: =IF(X31="","",NORMSINV((30-0.375)/(Yeterlilik!$N$24+0.25))) | AH31: =IF(X31="","",NORMSDIST((X31-Yeterlilik!$N$25)/Yeterlilik!$N$30)) | AI31: =IF(OR(X31="",AH31<=0,AH31>=1),0,(30*2-1)*(LN(AH31)+LN(1-INDEX($AH$2:$AH$126,Yeterlilik!$N$24+1-30)))) | AM31: =IF(B31="",NA(),B31-$AM$1) | AS31: =K31-$AM$1 | AT31: =N31-$AM$1 | AZ31: =IF(X31="",NA(),X31-$AM$1) | BB31: =IF(Y31="",NA(),Y31)
A32: =IF(B32="","",31) | B32: =IF(Yeterlilik!$B$39="","",Yeterlilik!$B$39) | K32: =$AD$1+15*$AF$1 | L32: =COUNTIFS($B$2:$B$126,">="&$AD$1+14*$AF$1,$B$2:$B$126,"<"&$AD$1+15*$AF$1) | N32: =$AD$1+30*(($AE$1-$AD$1)/119) | O32: =IF(Yeterlilik!$N$30=0,0,Yeterlilik!$N$24*$AF$1*NORMDIST(N32,Yeterlilik!$N$25,Yeterlilik!$N$30,FALSE)) | X32: =IF(31>Yeterlilik!$N$24,"",SMALL($B$2:$B$126,31)) | Y32: =IF(X32="","",NORMSINV((31-0.375)/(Yeterlilik!$N$24+0.25))) | AH32: =IF(X32="","",NORMSDIST((X32-Yeterlilik!$N$25)/Yeterlilik!$N$30)) | AI32: =IF(OR(X32="",AH32<=0,AH32>=1),0,(31*2-1)*(LN(AH32)+LN(1-INDEX($AH$2:$AH$126,Yeterlilik!$N$24+1-31)))) | AM32: =IF(B32="",NA(),B32-$AM$1) | AS32: =K32-$AM$1 | AT32: =N32-$AM$1 | AZ32: =IF(X32="",NA(),X32-$AM$1) | BB32: =IF(Y32="",NA(),Y32)
A33: =IF(B33="","",32) | B33: =IF(Yeterlilik!$B$40="","",Yeterlilik!$B$40) | K33: =$AD$1+15*$AF$1 | L33: =0 | N33: =$AD$1+31*(($AE$1-$AD$1)/119) | O33: =IF(Yeterlilik!$N$30=0,0,Yeterlilik!$N$24*$AF$1*NORMDIST(N33,Yeterlilik!$N$25,Yeterlilik!$N$30,FALSE)) | X33: =IF(32>Yeterlilik!$N$24,"",SMALL($B$2:$B$126,32)) | Y33: =IF(X33="","",NORMSINV((32-0.375)/(Yeterlilik!$N$24+0.25))) | AH33: =IF(X33="","",NORMSDIST((X33-Yeterlilik!$N$25)/Yeterlilik!$N$30)) | AI33: =IF(OR(X33="",AH33<=0,AH33>=1),0,(32*2-1)*(LN(AH33)+LN(1-INDEX($AH$2:$AH$126,Yeterlilik!$N$24+1-32)))) | AM33: =IF(B33="",NA(),B33-$AM$1) | AS33: =K33-$AM$1 | AT33: =N33-$AM$1 | AZ33: =IF(X33="",NA(),X33-$AM$1) | BB33: =IF(Y33="",NA(),Y33)
A34: =IF(B34="","",33) | B34: =IF(Yeterlilik!$B$41="","",Yeterlilik!$B$41) | K34: =NA() | L34: =NA() | N34: =$AD$1+32*(($AE$1-$AD$1)/119) | O34: =IF(Yeterlilik!$N$30=0,0,Yeterlilik!$N$24*$AF$1*NORMDIST(N34,Yeterlilik!$N$25,Yeterlilik!$N$30,FALSE)) | X34: =IF(33>Yeterlilik!$N$24,"",SMALL($B$2:$B$126,33)) | Y34: =IF(X34="","",NORMSINV((33-0.375)/(Yeterlilik!$N$24+0.25))) | AH34: =IF(X34="","",NORMSDIST((X34-Yeterlilik!$N$25)/Yeterlilik!$N$30)) | AI34: =IF(OR(X34="",AH34<=0,AH34>=1),0,(33*2-1)*(LN(AH34)+LN(1-INDEX($AH$2:$AH$126,Yeterlilik!$N$24+1-33)))) | AM34: =IF(B34="",NA(),B34-$AM$1) | AS34: =K34-$AM$1 | AT34: =N34-$AM$1 | AZ34: =IF(X34="",NA(),X34-$AM$1) | BB34: =IF(Y34="",NA(),Y34)
A35: =IF(B35="","",34) | B35: =IF(Yeterlilik!$B$42="","",Yeterlilik!$B$42) | K35: =NA() | L35: =NA() | N35: =$AD$1+33*(($AE$1-$AD$1)/119) | O35: =IF(Yeterlilik!$N$30=0,0,Yeterlilik!$N$24*$AF$1*NORMDIST(N35,Yeterlilik!$N$25,Yeterlilik!$N$30,FALSE)) | X35: =IF(34>Yeterlilik!$N$24,"",SMALL($B$2:$B$126,34)) | Y35: =IF(X35="","",NORMSINV((34-0.375)/(Yeterlilik!$N$24+0.25))) | AH35: =IF(X35="","",NORMSDIST((X35-Yeterlilik!$N$25)/Yeterlilik!$N$30)) | AI35: =IF(OR(X35="",AH35<=0,AH35>=1),0,(34*2-1)*(LN(AH35)+LN(1-INDEX($AH$2:$AH$126,Yeterlilik!$N$24+1-34)))) | AM35: =IF(B35="",NA(),B35-$AM$1) | AS35: =K35-$AM$1 | AT35: =N35-$AM$1 | AZ35: =IF(X35="",NA(),X35-$AM$1) | BB35: =IF(Y35="",NA(),Y35)
A36: =IF(B36="","",35) | B36: =IF(Yeterlilik!$B$43="","",Yeterlilik!$B$43) | K36: =NA() | L36: =NA() | N36: =$AD$1+34*(($AE$1-$AD$1)/119) | O36: =IF(Yeterlilik!$N$30=0,0,Yeterlilik!$N$24*$AF$1*NORMDIST(N36,Yeterlilik!$N$25,Yeterlilik!$N$30,FALSE)) | X36: =IF(35>Yeterlilik!$N$24,"",SMALL($B$2:$B$126,35)) | Y36: =IF(X36="","",NORMSINV((35-0.375)/(Yeterlilik!$N$24+0.25))) | AH36: =IF(X36="","",NORMSDIST((X36-Yeterlilik!$N$25)/Yeterlilik!$N$30)) | AI36: =IF(OR(X36="",AH36<=0,AH36>=1),0,(35*2-1)*(LN(AH36)+LN(1-INDEX($AH$2:$AH$126,Yeterlilik!$N$24+1-35)))) | AM36: =IF(B36="",NA(),B36-$AM$1) | AS36: =K36-$AM$1 | AT36: =N36-$AM$1 | AZ36: =IF(X36="",NA(),X36-$AM$1) | BB36: =IF(Y36="",NA(),Y36)
A37: =IF(B37="","",36) | B37: =IF(Yeterlilik!$B$44="","",Yeterlilik!$B$44) | K37: =NA() | L37: =NA() | N37: =$AD$1+35*(($AE$1-$AD$1)/119) | O37: =IF(Yeterlilik!$N$30=0,0,Yeterlilik!$N$24*$AF$1*NORMDIST(N37,Yeterlilik!$N$25,Yeterlilik!$N$30,FALSE)) | X37: =IF(36>Yeterlilik!$N$24,"",SMALL($B$2:$B$126,36)) | Y37: =IF(X37="","",NORMSINV((36-0.375)/(Yeterlilik!$N$24+0.25))) | AH37: =IF(X37="","",NORMSDIST((X37-Yeterlilik!$N$25)/Yeterlilik!$N$30)) | AI37: =IF(OR(X37="",AH37<=0,AH37>=1),0,(36*2-1)*(LN(AH37)+LN(1-INDEX($AH$2:$AH$126,Yeterlilik!$N$24+1-36)))) | AM37: =IF(B37="",NA(),B37-$AM$1) | AS37: =K37-$AM$1 | AT37: =N37-$AM$1 | AZ37: =IF(X37="",NA(),X37-$AM$1) | BB37: =IF(Y37="",NA(),Y37)
A38: =IF(B38="","",37) | B38: =IF(Yeterlilik!$B$45="","",Yeterlilik!$B$45) | K38: =NA() | L38: =NA() | N38: =$AD$1+36*(($AE$1-$AD$1)/119) | O38: =IF(Yeterlilik!$N$30=0,0,Yeterlilik!$N$24*$AF$1*NORMDIST(N38,Yeterlilik!$N$25,Yeterlilik!$N$30,FALSE)) | X38: =IF(37>Yeterlilik!$N$24,"",SMALL($B$2:$B$126,37)) | Y38: =IF(X38="","",NORMSINV((37-0.375)/(Yeterlilik!$N$24+0.25))) | AH38: =IF(X38="","",NORMSDIST((X38-Yeterlilik!$N$25)/Yeterlilik!$N$30)) | AI38: =IF(OR(X38="",AH38<=0,AH38>=1),0,(37*2-1)*(LN(AH38)+LN(1-INDEX($AH$2:$AH$126,Yeterlilik!$N$24+1-37)))) | AM38: =IF(B38="",NA(),B38-$AM$1) | AS38: =K38-$AM$1 | AT38: =N38-$AM$1 | AZ38: =IF(X38="",NA(),X38-$AM$1) | BB38: =IF(Y38="",NA(),Y38)
A39: =IF(B39="","",38) | B39: =IF(Yeterlilik!$B$46="","",Yeterlilik!$B$46) | K39: =NA() | L39: =NA() | N39: =$AD$1+37*(($AE$1-$AD$1)/119) | O39: =IF(Yeterlilik!$N$30=0,0,Yeterlilik!$N$24*$AF$1*NORMDIST(N39,Yeterlilik!$N$25,Yeterlilik!$N$30,FALSE)) | X39: =IF(38>Yeterlilik!$N$24,"",SMALL($B$2:$B$126,38)) | Y39: =IF(X39="","",NORMSINV((38-0.375)/(Yeterlilik!$N$24+0.25))) | AH39: =IF(X39="","",NORMSDIST((X39-Yeterlilik!$N$25)/Yeterlilik!$N$30)) | AI39: =IF(OR(X39="",AH39<=0,AH39>=1),0,(38*2-1)*(LN(AH39)+LN(1-INDEX($AH$2:$AH$126,Yeterlilik!$N$24+1-38)))) | AM39: =IF(B39="",NA(),B39-$AM$1) | AS39: =K39-$AM$1 | AT39: =N39-$AM$1 | AZ39: =IF(X39="",NA(),X39-$AM$1) | BB39: =IF(Y39="",NA(),Y39)
A40: =IF(B40="","",39) | B40: =IF(Yeterlilik!$B$47="","",Yeterlilik!$B$47) | K40: =NA() | L40: =NA() | N40: =$AD$1+38*(($AE$1-$AD$1)/119) | O40: =IF(Yeterlilik!$N$30=0,0,Yeterlilik!$N$24*$AF$1*NORMDIST(N40,Yeterlilik!$N$25,Yeterlilik!$N$30,FALSE)) | X40: =IF(39>Yeterlilik!$N$24,"",SMALL($B$2:$B$126,39)) | Y40: =IF(X40="","",NORMSINV((39-0.375)/(Yeterlilik!$N$24+0.25))) | AH40: =IF(X40="","",NORMSDIST((X40-Yeterlilik!$N$25)/Yeterlilik!$N$30)) | AI40: =IF(OR(X40="",AH40<=0,AH40>=1),0,(39*2-1)*(LN(AH40)+LN(1-INDEX($AH$2:$AH$126,Yeterlilik!$N$24+1-39)))) | AM40: =IF(B40="",NA(),B40-$AM$1) | AS40: =K40-$AM$1 | AT40: =N40-$AM$1 | AZ40: =IF(X40="",NA(),X40-$AM$1) | BB40: =IF(Y40="",NA(),Y40)
...
