Workbook

Sheet Yeterlilik
J1: PROSES VE MAKİNE YETERLİLİĞİ · NİTEL | AK1: Dok. No | AN1: FR24
AK2: Y. Tarihi | AN2: 02.01.2023
AK3: Rev. No | AN3: 01 / 25.08.2026
AK4: Sayfa | AN4: 1 / 1
A7: ALT GRUP VERİLERİ | J7: TANIMLAMA
A8: i | B8: n | C8: =IF(veri!$Z$3,"kusurlu d","hata c") | D8: =IF(veri!$Z$3,"% kusurlu","DPU") | E8: kart | F8: UCL | G8: LCL | H8: durum | J8: Ürün
A9: 1 | D9: =IF($B9="","",veri!K2) | E9: =IF($B9="","",veri!D2) | F9: =IF($B9="","",veri!G2) | G9: =IF($B9="","",veri!H2) | H9: =IF($B9="","",IF(OR(E9>F9,E9<G9),"KD","")) | J9: Müşteri
A10: 2 | D10: =IF($B10="","",veri!K3) | E10: =IF($B10="","",veri!D3) | F10: =IF($B10="","",veri!G3) | G10: =IF($B10="","",veri!H3) | H10: =IF($B10="","",IF(OR(E10>F10,E10<G10),"KD","")) | J10: Teknik resim
A11: 3 | D11: =IF($B11="","",veri!K4) | E11: =IF($B11="","",veri!D4) | F11: =IF($B11="","",veri!G4) | G11: =IF($B11="","",veri!H4) | H11: =IF($B11="","",IF(OR(E11>F11,E11<G11),"KD","")) | J11: Karakteristik / kontrol
A12: 4 | D12: =IF($B12="","",veri!K5) | E12: =IF($B12="","",veri!D5) | F12: =IF($B12="","",veri!G5) | G12: =IF($B12="","",veri!H5) | H12: =IF($B12="","",IF(OR(E12>F12,E12<G12),"KD","")) | J12: Kontrol yöntemi / cihaz
A13: 5 | D13: =IF($B13="","",veri!K6) | E13: =IF($B13="","",veri!D6) | F13: =IF($B13="","",veri!G6) | G13: =IF($B13="","",veri!H6) | H13: =IF($B13="","",IF(OR(E13>F13,E13<G13),"KD","")) | J13: Sorumlu
A14: 6 | D14: =IF($B14="","",veri!K7) | E14: =IF($B14="","",veri!D7) | F14: =IF($B14="","",veri!G7) | G14: =IF($B14="","",veri!H7) | H14: =IF($B14="","",IF(OR(E14>F14,E14<G14),"KD","")) | J14: Çalışmayı yapan
A15: 7 | D15: =IF($B15="","",veri!K8) | E15: =IF($B15="","",veri!D8) | F15: =IF($B15="","",veri!G8) | G15: =IF($B15="","",veri!H8) | H15: =IF($B15="","",IF(OR(E15>F15,E15<G15),"KD","")) | J15: Tarih
A16: 8 | D16: =IF($B16="","",veri!K9) | E16: =IF($B16="","",veri!D9) | F16: =IF($B16="","",veri!G9) | G16: =IF($B16="","",veri!H9) | H16: =IF($B16="","",IF(OR(E16>F16,E16<G16),"KD","")) | J16: Kart türü | N16: p
A17: 9 | D17: =IF($B17="","",veri!K10) | E17: =IF($B17="","",veri!D10) | F17: =IF($B17="","",veri!G10) | G17: =IF($B17="","",veri!H10) | H17: =IF($B17="","",IF(OR(E17>F17,E17<G17),"KD","")) | J17: Kart açıklaması | N17: =CHOOSE(veri!$Z$1,"p — kusurlu oranı (Binomial)","np — kusurlu adedi, sabit n (Binomial)","u — birim başına hata (Poisson)","c — hata adedi, sabit birim (Poisson)")
A18: 10 | D18: =IF($B18="","",veri!K11) | E18: =IF($B18="","",veri!D11) | F18: =IF($B18="","",veri!G11) | G18: =IF($B18="","",veri!H11) | H18: =IF($B18="","",IF(OR(E18>F18,E18<G18),"KD",""))
A19: 11 | D19: =IF($B19="","",veri!K12) | E19: =IF($B19="","",veri!D12) | F19: =IF($B19="","",veri!G12) | G19: =IF($B19="","",veri!H12) | H19: =IF($B19="","",IF(OR(E19>F19,E19<G19),"KD","")) | J19: HEDEF VE KABUL KRİTERİ
A20: 12 | D20: =IF($B20="","",veri!K13) | E20: =IF($B20="","",veri!D13) | F20: =IF($B20="","",veri!G13) | G20: =IF($B20="","",veri!H13) | H20: =IF($B20="","",IF(OR(E20>F20,E20<G20),"KD","")) | J20: Hedef (% kusurlu / DPU)
A21: 13 | D21: =IF($B21="","",veri!K14) | E21: =IF($B21="","",veri!D14) | F21: =IF($B21="","",veri!G14) | G21: =IF($B21="","",veri!H14) | H21: =IF($B21="","",IF(OR(E21>F21,E21<G21),"KD","")) | J21: Yeterli: Cpk eşd. ≥ | N21: 1.67
A22: 14 | D22: =IF($B22="","",veri!K15) | E22: =IF($B22="","",veri!D15) | F22: =IF($B22="","",veri!G15) | G22: =IF($B22="","",veri!H15) | H22: =IF($B22="","",IF(OR(E22>F22,E22<G22),"KD","")) | J22: Şartlı: Cpk eşd. ≥ | N22: 1.33
A23: 15 | D23: =IF($B23="","",veri!K16) | E23: =IF($B23="","",veri!D16) | F23: =IF($B23="","",veri!G16) | G23: =IF($B23="","",veri!H16) | H23: =IF($B23="","",IF(OR(E23>F23,E23<G23),"KD",""))
A24: 16 | D24: =IF($B24="","",veri!K17) | E24: =IF($B24="","",veri!D17) | F24: =IF($B24="","",veri!G17) | G24: =IF($B24="","",veri!H17) | H24: =IF($B24="","",IF(OR(E24>F24,E24<G24),"KD","")) | J24: İSTATİSTİK (canlı formül)
A25: 17 | D25: =IF($B25="","",veri!K18) | E25: =IF($B25="","",veri!D18) | F25: =IF($B25="","",veri!G18) | G25: =IF($B25="","",veri!H18) | H25: =IF($B25="","",IF(OR(E25>F25,E25<G25),"KD","")) | J25: Alt grup sayısı k | N25: =COUNT(B9:B58)
A26: 18 | D26: =IF($B26="","",veri!K19) | E26: =IF($B26="","",veri!D19) | F26: =IF($B26="","",veri!G19) | G26: =IF($B26="","",veri!H19) | H26: =IF($B26="","",IF(OR(E26>F26,E26<G26),"KD","")) | J26: Toplam n | N26: =SUM(B9:B58)
A27: 19 | D27: =IF($B27="","",veri!K20) | E27: =IF($B27="","",veri!D20) | F27: =IF($B27="","",veri!G20) | G27: =IF($B27="","",veri!H20) | H27: =IF($B27="","",IF(OR(E27>F27,E27<G27),"KD","")) | J27: Ortalama oran (p̄ / ū) | N27: =IF(N26=0,"",SUM(C9:C58)/N26)
A28: 20 | D28: =IF($B28="","",veri!K21) | E28: =IF($B28="","",veri!D21) | F28: =IF($B28="","",veri!G21) | G28: =IF($B28="","",veri!H21) | H28: =IF($B28="","",IF(OR(E28>F28,E28<G28),"KD","")) | J28: =IF(veri!$Z$3,"Toplam kusurlu","Toplam hata") | N28: =SUM(C9:C58)
A29: 21 | D29: =IF($B29="","",veri!K22) | E29: =IF($B29="","",veri!D22) | F29: =IF($B29="","",veri!G22) | G29: =IF($B29="","",veri!H22) | H29: =IF($B29="","",IF(OR(E29>F29,E29<G29),"KD","")) | J29: =IF(veri!$Z$3,"% kusurlu","DPU (birim başına)") | N29: =IF(N27="","",N27*IF(veri!$Z$3,100,1))
A30: 22 | D30: =IF($B30="","",veri!K23) | E30: =IF($B30="","",veri!D23) | F30: =IF($B30="","",veri!G23) | G30: =IF($B30="","",veri!H23) | H30: =IF($B30="","",IF(OR(E30>F30,E30<G30),"KD","")) | J30: =IF(veri!$Z$3,"PPM (kusurlu)","DPMO") | N30: =IF(N27="","",N27*1000000)
A31: 23 | D31: =IF($B31="","",veri!K24) | E31: =IF($B31="","",veri!D24) | F31: =IF($B31="","",veri!G24) | G31: =IF($B31="","",veri!H24) | H31: =IF($B31="","",IF(OR(E31>F31,E31<G31),"KD","")) | J31: %95 güven aralığı — alt | N31: =IF(N27="","",MAX(0,N27-1.96*SQRT(IF(veri!$Z$3,N27*(1-N27),N27)/N26))*IF(veri!$Z$3,100,1))
A32: 24 | D32: =IF($B32="","",veri!K25) | E32: =IF($B32="","",veri!D25) | F32: =IF($B32="","",veri!G25) | G32: =IF($B32="","",veri!H25) | H32: =IF($B32="","",IF(OR(E32>F32,E32<G32),"KD","")) | J32: %95 güven aralığı — üst | N32: =IF(N27="","",(N27+1.96*SQRT(IF(veri!$Z$3,N27*(1-N27),N27)/N26))*IF(veri!$Z$3,100,1))
A33: 25 | D33: =IF($B33="","",veri!K26) | E33: =IF($B33="","",veri!D26) | F33: =IF($B33="","",veri!G26) | G33: =IF($B33="","",veri!H26) | H33: =IF($B33="","",IF(OR(E33>F33,E33<G33),"KD","")) | J33: Kontrol dışı alt grup | N33: =COUNTIF(H9:H58,"KD")
A34: 26 | D34: =IF($B34="","",veri!K27) | E34: =IF($B34="","",veri!D27) | F34: =IF($B34="","",veri!G27) | G34: =IF($B34="","",veri!H27) | H34: =IF($B34="","",IF(OR(E34>F34,E34<G34),"KD",""))
A35: 27 | D35: =IF($B35="","",veri!K28) | E35: =IF($B35="","",veri!D28) | F35: =IF($B35="","",veri!G28) | G35: =IF($B35="","",veri!H28) | H35: =IF($B35="","",IF(OR(E35>F35,E35<G35),"KD","")) | J35: YETERLİLİK
A36: 28 | D36: =IF($B36="","",veri!K29) | E36: =IF($B36="","",veri!D29) | F36: =IF($B36="","",veri!G29) | G36: =IF($B36="","",veri!H29) | H36: =IF($B36="","",IF(OR(E36>F36,E36<G36),"KD","")) | J36: Süreç Z | N36: =IF(OR(N27="",N28=0),"",IF(veri!$Z$3,NORMSINV(1-N27),NORMSINV(EXP(-N27))))
A37: 29 | D37: =IF($B37="","",veri!K30) | E37: =IF($B37="","",veri!D30) | F37: =IF($B37="","",veri!G30) | G37: =IF($B37="","",veri!H30) | H37: =IF($B37="","",IF(OR(E37>F37,E37<G37),"KD","")) | J37: Cpk eşdeğeri (Z / 3) | N37: =IF(N36="","",N36/3)
A38: 30 | D38: =IF($B38="","",veri!K31) | E38: =IF($B38="","",veri!D31) | F38: =IF($B38="","",veri!G31) | G38: =IF($B38="","",veri!H31) | H38: =IF($B38="","",IF(OR(E38>F38,E38<G38),"KD","")) | J38: Yöntem | N38: =IF(veri!$Z$3,"Binomial: Z = NORMSINV(1 − p̄)","Poisson: Z = NORMSINV(e^−DPU)")
A39: 31 | D39: =IF($B39="","",veri!K32) | E39: =IF($B39="","",veri!D32) | F39: =IF($B39="","",veri!G32) | G39: =IF($B39="","",veri!H32) | H39: =IF($B39="","",IF(OR(E39>F39,E39<G39),"KD",""))
A40: 32 | D40: =IF($B40="","",veri!K33) | E40: =IF($B40="","",veri!D33) | F40: =IF($B40="","",veri!G33) | G40: =IF($B40="","",veri!H33) | H40: =IF($B40="","",IF(OR(E40>F40,E40<G40),"KD","")) | J40: ="DEĞERLENDİRME: "&IF(N37="","— (hiç kusur yok: Cpk eşdeğeri hesaplanamaz)",IF(N33>0,"KARARSIZ — önce özel sebepleri giderin",IF(N37>=N21,"YETERLİ",IF(N37>=N22,"ŞARTLI KABUL","YETERSİZ"))))&IF(N37="",""," (Cpk eşd. = "&ROUND(N37,2)&")")
A41: 33 | D41: =IF($B41="","",veri!K34) | E41: =IF($B41="","",veri!D34) | F41: =IF($B41="","",veri!G34) | G41: =IF($B41="","",veri!H34) | H41: =IF($B41="","",IF(OR(E41>F41,E41<G41),"KD",""))
A42: 34 | D42: =IF($B42="","",veri!K35) | E42: =IF($B42="","",veri!D35) | F42: =IF($B42="","",veri!G35) | G42: =IF($B42="","",veri!H35) | H42: =IF($B42="","",IF(OR(E42>F42,E42<G42),"KD","")) | J42: ="Kabul: Cpk eşdeğeri ≥ "&N21&" yeterli · "&N22&"–"&N21&" müşteri temsilcisiyle gözden geçirilir · < "&N22&" yetersiz. Kontrol sınırları ±3σ."
...

Sheet veri
A1: i | B1: n | C1: x | D1: kart değeri | E1: CL | F1: sigma | G1: UCL | H1: LCL | I1: kümülatif | J1: nihai | K1: oran | M1: kutu orta | N1: adet | Y1: kart no | Z1: =IFERROR(MATCH(Yeterlilik!$N$16,{"p","np","u","c"},0),1)
A2: =IF(OR(Yeterlilik!$B9="",Yeterlilik!$C9=""),NA(),1) | B2: =IF(OR(Yeterlilik!$B9="",Yeterlilik!$C9=""),NA(),Yeterlilik!$B9) | C2: =IF(OR(Yeterlilik!$B9="",Yeterlilik!$C9=""),NA(),Yeterlilik!$C9) | D2: =IF(OR(Yeterlilik!$B9="",Yeterlilik!$C9=""),NA(),CHOOSE($Z$1,C2/B2*100,C2,C2/B2,C2)) | E2: =IF(OR(Yeterlilik!$B9="",Yeterlilik!$C9=""),NA(),CHOOSE($Z$1,$Z$2*100,B2*$Z$2,$Z$2,B2*$Z$2)) | F2: =IF(OR(Yeterlilik!$B9="",Yeterlilik!$C9=""),NA(),CHOOSE($Z$1,SQRT($Z$2*(1-$Z$2)/B2)*100,SQRT(B2*$Z$2*(1-$Z$2)),SQRT($Z$2/B2),SQRT(B2*$Z$2))) | G2: =IF(OR(Yeterlilik!$B9="",Yeterlilik!$C9=""),NA(),E2+3*F2) | H2: =IF(OR(Yeterlilik!$B9="",Yeterlilik!$C9=""),NA(),MAX(0,E2-3*F2)) | I2: =IF(OR(Yeterlilik!$B9="",Yeterlilik!$C9=""),NA(),SUM(Yeterlilik!$C$9:$C9)/SUM(Yeterlilik!$B$9:$B9)*IF($Z$3,100,1)) | J2: =IF(OR(Yeterlilik!$B9="",Yeterlilik!$C9=""),NA(),$Z$2*IF($Z$3,100,1)) | K2: =IF(OR(Yeterlilik!$B9="",Yeterlilik!$C9=""),NA(),C2/B2*IF($Z$3,100,1)) | M2: =$Z$4+(0+0.5)*$Z$5 | N2: =COUNTIFS($K$2:$K$51,">="&($Z$4+0*$Z$5),$K$2:$K$51,"<"&($Z$4+1*$Z$5)) | Y2: oran | Z2: =IF(Yeterlilik!$N$27="",0,Yeterlilik!$N$27)
A3: =IF(OR(Yeterlilik!$B10="",Yeterlilik!$C10=""),NA(),2) | B3: =IF(OR(Yeterlilik!$B10="",Yeterlilik!$C10=""),NA(),Yeterlilik!$B10) | C3: =IF(OR(Yeterlilik!$B10="",Yeterlilik!$C10=""),NA(),Yeterlilik!$C10) | D3: =IF(OR(Yeterlilik!$B10="",Yeterlilik!$C10=""),NA(),CHOOSE($Z$1,C3/B3*100,C3,C3/B3,C3)) | E3: =IF(OR(Yeterlilik!$B10="",Yeterlilik!$C10=""),NA(),CHOOSE($Z$1,$Z$2*100,B3*$Z$2,$Z$2,B3*$Z$2)) | F3: =IF(OR(Yeterlilik!$B10="",Yeterlilik!$C10=""),NA(),CHOOSE($Z$1,SQRT($Z$2*(1-$Z$2)/B3)*100,SQRT(B3*$Z$2*(1-$Z$2)),SQRT($Z$2/B3),SQRT(B3*$Z$2))) | G3: =IF(OR(Yeterlilik!$B10="",Yeterlilik!$C10=""),NA(),E3+3*F3) | H3: =IF(OR(Yeterlilik!$B10="",Yeterlilik!$C10=""),NA(),MAX(0,E3-3*F3)) | I3: =IF(OR(Yeterlilik!$B10="",Yeterlilik!$C10=""),NA(),SUM(Yeterlilik!$C$9:$C10)/SUM(Yeterlilik!$B$9:$B10)*IF($Z$3,100,1)) | J3: =IF(OR(Yeterlilik!$B10="",Yeterlilik!$C10=""),NA(),$Z$2*IF($Z$3,100,1)) | K3: =IF(OR(Yeterlilik!$B10="",Yeterlilik!$C10=""),NA(),C3/B3*IF($Z$3,100,1)) | M3: =$Z$4+(1+0.5)*$Z$5 | N3: =COUNTIFS($K$2:$K$51,">="&($Z$4+1*$Z$5),$K$2:$K$51,"<"&($Z$4+2*$Z$5)) | Y3: binom | Z3: =$Z$1<=2
A4: =IF(OR(Yeterlilik!$B11="",Yeterlilik!$C11=""),NA(),3) | B4: =IF(OR(Yeterlilik!$B11="",Yeterlilik!$C11=""),NA(),Yeterlilik!$B11) | C4: =IF(OR(Yeterlilik!$B11="",Yeterlilik!$C11=""),NA(),Yeterlilik!$C11) | D4: =IF(OR(Yeterlilik!$B11="",Yeterlilik!$C11=""),NA(),CHOOSE($Z$1,C4/B4*100,C4,C4/B4,C4)) | E4: =IF(OR(Yeterlilik!$B11="",Yeterlilik!$C11=""),NA(),CHOOSE($Z$1,$Z$2*100,B4*$Z$2,$Z$2,B4*$Z$2)) | F4: =IF(OR(Yeterlilik!$B11="",Yeterlilik!$C11=""),NA(),CHOOSE($Z$1,SQRT($Z$2*(1-$Z$2)/B4)*100,SQRT(B4*$Z$2*(1-$Z$2)),SQRT($Z$2/B4),SQRT(B4*$Z$2))) | G4: =IF(OR(Yeterlilik!$B11="",Yeterlilik!$C11=""),NA(),E4+3*F4) | H4: =IF(OR(Yeterlilik!$B11="",Yeterlilik!$C11=""),NA(),MAX(0,E4-3*F4)) | I4: =IF(OR(Yeterlilik!$B11="",Yeterlilik!$C11=""),NA(),SUM(Yeterlilik!$C$9:$C11)/SUM(Yeterlilik!$B$9:$B11)*IF($Z$3,100,1)) | J4: =IF(OR(Yeterlilik!$B11="",Yeterlilik!$C11=""),NA(),$Z$2*IF($Z$3,100,1)) | K4: =IF(OR(Yeterlilik!$B11="",Yeterlilik!$C11=""),NA(),C4/B4*IF($Z$3,100,1)) | M4: =$Z$4+(2+0.5)*$Z$5 | N4: =COUNTIFS($K$2:$K$51,">="&($Z$4+2*$Z$5),$K$2:$K$51,"<"&($Z$4+3*$Z$5)) | Y4: hist alt | Z4: =IFERROR(_xlfn.AGGREGATE(5,6,$K$2:$K$51),0)
A5: =IF(OR(Yeterlilik!$B12="",Yeterlilik!$C12=""),NA(),4) | B5: =IF(OR(Yeterlilik!$B12="",Yeterlilik!$C12=""),NA(),Yeterlilik!$B12) | C5: =IF(OR(Yeterlilik!$B12="",Yeterlilik!$C12=""),NA(),Yeterlilik!$C12) | D5: =IF(OR(Yeterlilik!$B12="",Yeterlilik!$C12=""),NA(),CHOOSE($Z$1,C5/B5*100,C5,C5/B5,C5)) | E5: =IF(OR(Yeterlilik!$B12="",Yeterlilik!$C12=""),NA(),CHOOSE($Z$1,$Z$2*100,B5*$Z$2,$Z$2,B5*$Z$2)) | F5: =IF(OR(Yeterlilik!$B12="",Yeterlilik!$C12=""),NA(),CHOOSE($Z$1,SQRT($Z$2*(1-$Z$2)/B5)*100,SQRT(B5*$Z$2*(1-$Z$2)),SQRT($Z$2/B5),SQRT(B5*$Z$2))) | G5: =IF(OR(Yeterlilik!$B12="",Yeterlilik!$C12=""),NA(),E5+3*F5) | H5: =IF(OR(Yeterlilik!$B12="",Yeterlilik!$C12=""),NA(),MAX(0,E5-3*F5)) | I5: =IF(OR(Yeterlilik!$B12="",Yeterlilik!$C12=""),NA(),SUM(Yeterlilik!$C$9:$C12)/SUM(Yeterlilik!$B$9:$B12)*IF($Z$3,100,1)) | J5: =IF(OR(Yeterlilik!$B12="",Yeterlilik!$C12=""),NA(),$Z$2*IF($Z$3,100,1)) | K5: =IF(OR(Yeterlilik!$B12="",Yeterlilik!$C12=""),NA(),C5/B5*IF($Z$3,100,1)) | M5: =$Z$4+(3+0.5)*$Z$5 | N5: =COUNTIFS($K$2:$K$51,">="&($Z$4+3*$Z$5),$K$2:$K$51,"<"&($Z$4+4*$Z$5)) | Y5: hist adım | Z5: =IFERROR(IF(_xlfn.AGGREGATE(4,6,$K$2:$K$51)>$Z$4,(_xlfn.AGGREGATE(4,6,$K$2:$K$51)-$Z$4)/10,1),1)
A6: =IF(OR(Yeterlilik!$B13="",Yeterlilik!$C13=""),NA(),5) | B6: =IF(OR(Yeterlilik!$B13="",Yeterlilik!$C13=""),NA(),Yeterlilik!$B13) | C6: =IF(OR(Yeterlilik!$B13="",Yeterlilik!$C13=""),NA(),Yeterlilik!$C13) | D6: =IF(OR(Yeterlilik!$B13="",Yeterlilik!$C13=""),NA(),CHOOSE($Z$1,C6/B6*100,C6,C6/B6,C6)) | E6: =IF(OR(Yeterlilik!$B13="",Yeterlilik!$C13=""),NA(),CHOOSE($Z$1,$Z$2*100,B6*$Z$2,$Z$2,B6*$Z$2)) | F6: =IF(OR(Yeterlilik!$B13="",Yeterlilik!$C13=""),NA(),CHOOSE($Z$1,SQRT($Z$2*(1-$Z$2)/B6)*100,SQRT(B6*$Z$2*(1-$Z$2)),SQRT($Z$2/B6),SQRT(B6*$Z$2))) | G6: =IF(OR(Yeterlilik!$B13="",Yeterlilik!$C13=""),NA(),E6+3*F6) | H6: =IF(OR(Yeterlilik!$B13="",Yeterlilik!$C13=""),NA(),MAX(0,E6-3*F6)) | I6: =IF(OR(Yeterlilik!$B13="",Yeterlilik!$C13=""),NA(),SUM(Yeterlilik!$C$9:$C13)/SUM(Yeterlilik!$B$9:$B13)*IF($Z$3,100,1)) | J6: =IF(OR(Yeterlilik!$B13="",Yeterlilik!$C13=""),NA(),$Z$2*IF($Z$3,100,1)) | K6: =IF(OR(Yeterlilik!$B13="",Yeterlilik!$C13=""),NA(),C6/B6*IF($Z$3,100,1)) | M6: =$Z$4+(4+0.5)*$Z$5 | N6: =COUNTIFS($K$2:$K$51,">="&($Z$4+4*$Z$5),$K$2:$K$51,"<"&($Z$4+5*$Z$5))
A7: =IF(OR(Yeterlilik!$B14="",Yeterlilik!$C14=""),NA(),6) | B7: =IF(OR(Yeterlilik!$B14="",Yeterlilik!$C14=""),NA(),Yeterlilik!$B14) | C7: =IF(OR(Yeterlilik!$B14="",Yeterlilik!$C14=""),NA(),Yeterlilik!$C14) | D7: =IF(OR(Yeterlilik!$B14="",Yeterlilik!$C14=""),NA(),CHOOSE($Z$1,C7/B7*100,C7,C7/B7,C7)) | E7: =IF(OR(Yeterlilik!$B14="",Yeterlilik!$C14=""),NA(),CHOOSE($Z$1,$Z$2*100,B7*$Z$2,$Z$2,B7*$Z$2)) | F7: =IF(OR(Yeterlilik!$B14="",Yeterlilik!$C14=""),NA(),CHOOSE($Z$1,SQRT($Z$2*(1-$Z$2)/B7)*100,SQRT(B7*$Z$2*(1-$Z$2)),SQRT($Z$2/B7),SQRT(B7*$Z$2))) | G7: =IF(OR(Yeterlilik!$B14="",Yeterlilik!$C14=""),NA(),E7+3*F7) | H7: =IF(OR(Yeterlilik!$B14="",Yeterlilik!$C14=""),NA(),MAX(0,E7-3*F7)) | I7: =IF(OR(Yeterlilik!$B14="",Yeterlilik!$C14=""),NA(),SUM(Yeterlilik!$C$9:$C14)/SUM(Yeterlilik!$B$9:$B14)*IF($Z$3,100,1)) | J7: =IF(OR(Yeterlilik!$B14="",Yeterlilik!$C14=""),NA(),$Z$2*IF($Z$3,100,1)) | K7: =IF(OR(Yeterlilik!$B14="",Yeterlilik!$C14=""),NA(),C7/B7*IF($Z$3,100,1)) | M7: =$Z$4+(5+0.5)*$Z$5 | N7: =COUNTIFS($K$2:$K$51,">="&($Z$4+5*$Z$5),$K$2:$K$51,"<"&($Z$4+6*$Z$5))
A8: =IF(OR(Yeterlilik!$B15="",Yeterlilik!$C15=""),NA(),7) | B8: =IF(OR(Yeterlilik!$B15="",Yeterlilik!$C15=""),NA(),Yeterlilik!$B15) | C8: =IF(OR(Yeterlilik!$B15="",Yeterlilik!$C15=""),NA(),Yeterlilik!$C15) | D8: =IF(OR(Yeterlilik!$B15="",Yeterlilik!$C15=""),NA(),CHOOSE($Z$1,C8/B8*100,C8,C8/B8,C8)) | E8: =IF(OR(Yeterlilik!$B15="",Yeterlilik!$C15=""),NA(),CHOOSE($Z$1,$Z$2*100,B8*$Z$2,$Z$2,B8*$Z$2)) | F8: =IF(OR(Yeterlilik!$B15="",Yeterlilik!$C15=""),NA(),CHOOSE($Z$1,SQRT($Z$2*(1-$Z$2)/B8)*100,SQRT(B8*$Z$2*(1-$Z$2)),SQRT($Z$2/B8),SQRT(B8*$Z$2))) | G8: =IF(OR(Yeterlilik!$B15="",Yeterlilik!$C15=""),NA(),E8+3*F8) | H8: =IF(OR(Yeterlilik!$B15="",Yeterlilik!$C15=""),NA(),MAX(0,E8-3*F8)) | I8: =IF(OR(Yeterlilik!$B15="",Yeterlilik!$C15=""),NA(),SUM(Yeterlilik!$C$9:$C15)/SUM(Yeterlilik!$B$9:$B15)*IF($Z$3,100,1)) | J8: =IF(OR(Yeterlilik!$B15="",Yeterlilik!$C15=""),NA(),$Z$2*IF($Z$3,100,1)) | K8: =IF(OR(Yeterlilik!$B15="",Yeterlilik!$C15=""),NA(),C8/B8*IF($Z$3,100,1)) | M8: =$Z$4+(6+0.5)*$Z$5 | N8: =COUNTIFS($K$2:$K$51,">="&($Z$4+6*$Z$5),$K$2:$K$51,"<"&($Z$4+7*$Z$5))
A9: =IF(OR(Yeterlilik!$B16="",Yeterlilik!$C16=""),NA(),8) | B9: =IF(OR(Yeterlilik!$B16="",Yeterlilik!$C16=""),NA(),Yeterlilik!$B16) | C9: =IF(OR(Yeterlilik!$B16="",Yeterlilik!$C16=""),NA(),Yeterlilik!$C16) | D9: =IF(OR(Yeterlilik!$B16="",Yeterlilik!$C16=""),NA(),CHOOSE($Z$1,C9/B9*100,C9,C9/B9,C9)) | E9: =IF(OR(Yeterlilik!$B16="",Yeterlilik!$C16=""),NA(),CHOOSE($Z$1,$Z$2*100,B9*$Z$2,$Z$2,B9*$Z$2)) | F9: =IF(OR(Yeterlilik!$B16="",Yeterlilik!$C16=""),NA(),CHOOSE($Z$1,SQRT($Z$2*(1-$Z$2)/B9)*100,SQRT(B9*$Z$2*(1-$Z$2)),SQRT($Z$2/B9),SQRT(B9*$Z$2))) | G9: =IF(OR(Yeterlilik!$B16="",Yeterlilik!$C16=""),NA(),E9+3*F9) | H9: =IF(OR(Yeterlilik!$B16="",Yeterlilik!$C16=""),NA(),MAX(0,E9-3*F9)) | I9: =IF(OR(Yeterlilik!$B16="",Yeterlilik!$C16=""),NA(),SUM(Yeterlilik!$C$9:$C16)/SUM(Yeterlilik!$B$9:$B16)*IF($Z$3,100,1)) | J9: =IF(OR(Yeterlilik!$B16="",Yeterlilik!$C16=""),NA(),$Z$2*IF($Z$3,100,1)) | K9: =IF(OR(Yeterlilik!$B16="",Yeterlilik!$C16=""),NA(),C9/B9*IF($Z$3,100,1)) | M9: =$Z$4+(7+0.5)*$Z$5 | N9: =COUNTIFS($K$2:$K$51,">="&($Z$4+7*$Z$5),$K$2:$K$51,"<"&($Z$4+8*$Z$5))
A10: =IF(OR(Yeterlilik!$B17="",Yeterlilik!$C17=""),NA(),9) | B10: =IF(OR(Yeterlilik!$B17="",Yeterlilik!$C17=""),NA(),Yeterlilik!$B17) | C10: =IF(OR(Yeterlilik!$B17="",Yeterlilik!$C17=""),NA(),Yeterlilik!$C17) | D10: =IF(OR(Yeterlilik!$B17="",Yeterlilik!$C17=""),NA(),CHOOSE($Z$1,C10/B10*100,C10,C10/B10,C10)) | E10: =IF(OR(Yeterlilik!$B17="",Yeterlilik!$C17=""),NA(),CHOOSE($Z$1,$Z$2*100,B10*$Z$2,$Z$2,B10*$Z$2)) | F10: =IF(OR(Yeterlilik!$B17="",Yeterlilik!$C17=""),NA(),CHOOSE($Z$1,SQRT($Z$2*(1-$Z$2)/B10)*100,SQRT(B10*$Z$2*(1-$Z$2)),SQRT($Z$2/B10),SQRT(B10*$Z$2))) | G10: =IF(OR(Yeterlilik!$B17="",Yeterlilik!$C17=""),NA(),E10+3*F10) | H10: =IF(OR(Yeterlilik!$B17="",Yeterlilik!$C17=""),NA(),MAX(0,E10-3*F10)) | I10: =IF(OR(Yeterlilik!$B17="",Yeterlilik!$C17=""),NA(),SUM(Yeterlilik!$C$9:$C17)/SUM(Yeterlilik!$B$9:$B17)*IF($Z$3,100,1)) | J10: =IF(OR(Yeterlilik!$B17="",Yeterlilik!$C17=""),NA(),$Z$2*IF($Z$3,100,1)) | K10: =IF(OR(Yeterlilik!$B17="",Yeterlilik!$C17=""),NA(),C10/B10*IF($Z$3,100,1)) | M10: =$Z$4+(8+0.5)*$Z$5 | N10: =COUNTIFS($K$2:$K$51,">="&($Z$4+8*$Z$5),$K$2:$K$51,"<"&($Z$4+9*$Z$5))
A11: =IF(OR(Yeterlilik!$B18="",Yeterlilik!$C18=""),NA(),10) | B11: =IF(OR(Yeterlilik!$B18="",Yeterlilik!$C18=""),NA(),Yeterlilik!$B18) | C11: =IF(OR(Yeterlilik!$B18="",Yeterlilik!$C18=""),NA(),Yeterlilik!$C18) | D11: =IF(OR(Yeterlilik!$B18="",Yeterlilik!$C18=""),NA(),CHOOSE($Z$1,C11/B11*100,C11,C11/B11,C11)) | E11: =IF(OR(Yeterlilik!$B18="",Yeterlilik!$C18=""),NA(),CHOOSE($Z$1,$Z$2*100,B11*$Z$2,$Z$2,B11*$Z$2)) | F11: =IF(OR(Yeterlilik!$B18="",Yeterlilik!$C18=""),NA(),CHOOSE($Z$1,SQRT($Z$2*(1-$Z$2)/B11)*100,SQRT(B11*$Z$2*(1-$Z$2)),SQRT($Z$2/B11),SQRT(B11*$Z$2))) | G11: =IF(OR(Yeterlilik!$B18="",Yeterlilik!$C18=""),NA(),E11+3*F11) | H11: =IF(OR(Yeterlilik!$B18="",Yeterlilik!$C18=""),NA(),MAX(0,E11-3*F11)) | I11: =IF(OR(Yeterlilik!$B18="",Yeterlilik!$C18=""),NA(),SUM(Yeterlilik!$C$9:$C18)/SUM(Yeterlilik!$B$9:$B18)*IF($Z$3,100,1)) | J11: =IF(OR(Yeterlilik!$B18="",Yeterlilik!$C18=""),NA(),$Z$2*IF($Z$3,100,1)) | K11: =IF(OR(Yeterlilik!$B18="",Yeterlilik!$C18=""),NA(),C11/B11*IF($Z$3,100,1)) | M11: =$Z$4+(9+0.5)*$Z$5 | N11: =COUNTIFS($K$2:$K$51,">="&($Z$4+9*$Z$5),$K$2:$K$51,"<="&($Z$4+10*$Z$5))
A12: =IF(OR(Yeterlilik!$B19="",Yeterlilik!$C19=""),NA(),11) | B12: =IF(OR(Yeterlilik!$B19="",Yeterlilik!$C19=""),NA(),Yeterlilik!$B19) | C12: =IF(OR(Yeterlilik!$B19="",Yeterlilik!$C19=""),NA(),Yeterlilik!$C19) | D12: =IF(OR(Yeterlilik!$B19="",Yeterlilik!$C19=""),NA(),CHOOSE($Z$1,C12/B12*100,C12,C12/B12,C12)) | E12: =IF(OR(Yeterlilik!$B19="",Yeterlilik!$C19=""),NA(),CHOOSE($Z$1,$Z$2*100,B12*$Z$2,$Z$2,B12*$Z$2)) | F12: =IF(OR(Yeterlilik!$B19="",Yeterlilik!$C19=""),NA(),CHOOSE($Z$1,SQRT($Z$2*(1-$Z$2)/B12)*100,SQRT(B12*$Z$2*(1-$Z$2)),SQRT($Z$2/B12),SQRT(B12*$Z$2))) | G12: =IF(OR(Yeterlilik!$B19="",Yeterlilik!$C19=""),NA(),E12+3*F12) | H12: =IF(OR(Yeterlilik!$B19="",Yeterlilik!$C19=""),NA(),MAX(0,E12-3*F12)) | I12: =IF(OR(Yeterlilik!$B19="",Yeterlilik!$C19=""),NA(),SUM(Yeterlilik!$C$9:$C19)/SUM(Yeterlilik!$B$9:$B19)*IF($Z$3,100,1)) | J12: =IF(OR(Yeterlilik!$B19="",Yeterlilik!$C19=""),NA(),$Z$2*IF($Z$3,100,1)) | K12: =IF(OR(Yeterlilik!$B19="",Yeterlilik!$C19=""),NA(),C12/B12*IF($Z$3,100,1))
A13: =IF(OR(Yeterlilik!$B20="",Yeterlilik!$C20=""),NA(),12) | B13: =IF(OR(Yeterlilik!$B20="",Yeterlilik!$C20=""),NA(),Yeterlilik!$B20) | C13: =IF(OR(Yeterlilik!$B20="",Yeterlilik!$C20=""),NA(),Yeterlilik!$C20) | D13: =IF(OR(Yeterlilik!$B20="",Yeterlilik!$C20=""),NA(),CHOOSE($Z$1,C13/B13*100,C13,C13/B13,C13)) | E13: =IF(OR(Yeterlilik!$B20="",Yeterlilik!$C20=""),NA(),CHOOSE($Z$1,$Z$2*100,B13*$Z$2,$Z$2,B13*$Z$2)) | F13: =IF(OR(Yeterlilik!$B20="",Yeterlilik!$C20=""),NA(),CHOOSE($Z$1,SQRT($Z$2*(1-$Z$2)/B13)*100,SQRT(B13*$Z$2*(1-$Z$2)),SQRT($Z$2/B13),SQRT(B13*$Z$2))) | G13: =IF(OR(Yeterlilik!$B20="",Yeterlilik!$C20=""),NA(),E13+3*F13) | H13: =IF(OR(Yeterlilik!$B20="",Yeterlilik!$C20=""),NA(),MAX(0,E13-3*F13)) | I13: =IF(OR(Yeterlilik!$B20="",Yeterlilik!$C20=""),NA(),SUM(Yeterlilik!$C$9:$C20)/SUM(Yeterlilik!$B$9:$B20)*IF($Z$3,100,1)) | J13: =IF(OR(Yeterlilik!$B20="",Yeterlilik!$C20=""),NA(),$Z$2*IF($Z$3,100,1)) | K13: =IF(OR(Yeterlilik!$B20="",Yeterlilik!$C20=""),NA(),C13/B13*IF($Z$3,100,1))
A14: =IF(OR(Yeterlilik!$B21="",Yeterlilik!$C21=""),NA(),13) | B14: =IF(OR(Yeterlilik!$B21="",Yeterlilik!$C21=""),NA(),Yeterlilik!$B21) | C14: =IF(OR(Yeterlilik!$B21="",Yeterlilik!$C21=""),NA(),Yeterlilik!$C21) | D14: =IF(OR(Yeterlilik!$B21="",Yeterlilik!$C21=""),NA(),CHOOSE($Z$1,C14/B14*100,C14,C14/B14,C14)) | E14: =IF(OR(Yeterlilik!$B21="",Yeterlilik!$C21=""),NA(),CHOOSE($Z$1,$Z$2*100,B14*$Z$2,$Z$2,B14*$Z$2)) | F14: =IF(OR(Yeterlilik!$B21="",Yeterlilik!$C21=""),NA(),CHOOSE($Z$1,SQRT($Z$2*(1-$Z$2)/B14)*100,SQRT(B14*$Z$2*(1-$Z$2)),SQRT($Z$2/B14),SQRT(B14*$Z$2))) | G14: =IF(OR(Yeterlilik!$B21="",Yeterlilik!$C21=""),NA(),E14+3*F14) | H14: =IF(OR(Yeterlilik!$B21="",Yeterlilik!$C21=""),NA(),MAX(0,E14-3*F14)) | I14: =IF(OR(Yeterlilik!$B21="",Yeterlilik!$C21=""),NA(),SUM(Yeterlilik!$C$9:$C21)/SUM(Yeterlilik!$B$9:$B21)*IF($Z$3,100,1)) | J14: =IF(OR(Yeterlilik!$B21="",Yeterlilik!$C21=""),NA(),$Z$2*IF($Z$3,100,1)) | K14: =IF(OR(Yeterlilik!$B21="",Yeterlilik!$C21=""),NA(),C14/B14*IF($Z$3,100,1))
A15: =IF(OR(Yeterlilik!$B22="",Yeterlilik!$C22=""),NA(),14) | B15: =IF(OR(Yeterlilik!$B22="",Yeterlilik!$C22=""),NA(),Yeterlilik!$B22) | C15: =IF(OR(Yeterlilik!$B22="",Yeterlilik!$C22=""),NA(),Yeterlilik!$C22) | D15: =IF(OR(Yeterlilik!$B22="",Yeterlilik!$C22=""),NA(),CHOOSE($Z$1,C15/B15*100,C15,C15/B15,C15)) | E15: =IF(OR(Yeterlilik!$B22="",Yeterlilik!$C22=""),NA(),CHOOSE($Z$1,$Z$2*100,B15*$Z$2,$Z$2,B15*$Z$2)) | F15: =IF(OR(Yeterlilik!$B22="",Yeterlilik!$C22=""),NA(),CHOOSE($Z$1,SQRT($Z$2*(1-$Z$2)/B15)*100,SQRT(B15*$Z$2*(1-$Z$2)),SQRT($Z$2/B15),SQRT(B15*$Z$2))) | G15: =IF(OR(Yeterlilik!$B22="",Yeterlilik!$C22=""),NA(),E15+3*F15) | H15: =IF(OR(Yeterlilik!$B22="",Yeterlilik!$C22=""),NA(),MAX(0,E15-3*F15)) | I15: =IF(OR(Yeterlilik!$B22="",Yeterlilik!$C22=""),NA(),SUM(Yeterlilik!$C$9:$C22)/SUM(Yeterlilik!$B$9:$B22)*IF($Z$3,100,1)) | J15: =IF(OR(Yeterlilik!$B22="",Yeterlilik!$C22=""),NA(),$Z$2*IF($Z$3,100,1)) | K15: =IF(OR(Yeterlilik!$B22="",Yeterlilik!$C22=""),NA(),C15/B15*IF($Z$3,100,1))
A16: =IF(OR(Yeterlilik!$B23="",Yeterlilik!$C23=""),NA(),15) | B16: =IF(OR(Yeterlilik!$B23="",Yeterlilik!$C23=""),NA(),Yeterlilik!$B23) | C16: =IF(OR(Yeterlilik!$B23="",Yeterlilik!$C23=""),NA(),Yeterlilik!$C23) | D16: =IF(OR(Yeterlilik!$B23="",Yeterlilik!$C23=""),NA(),CHOOSE($Z$1,C16/B16*100,C16,C16/B16,C16)) | E16: =IF(OR(Yeterlilik!$B23="",Yeterlilik!$C23=""),NA(),CHOOSE($Z$1,$Z$2*100,B16*$Z$2,$Z$2,B16*$Z$2)) | F16: =IF(OR(Yeterlilik!$B23="",Yeterlilik!$C23=""),NA(),CHOOSE($Z$1,SQRT($Z$2*(1-$Z$2)/B16)*100,SQRT(B16*$Z$2*(1-$Z$2)),SQRT($Z$2/B16),SQRT(B16*$Z$2))) | G16: =IF(OR(Yeterlilik!$B23="",Yeterlilik!$C23=""),NA(),E16+3*F16) | H16: =IF(OR(Yeterlilik!$B23="",Yeterlilik!$C23=""),NA(),MAX(0,E16-3*F16)) | I16: =IF(OR(Yeterlilik!$B23="",Yeterlilik!$C23=""),NA(),SUM(Yeterlilik!$C$9:$C23)/SUM(Yeterlilik!$B$9:$B23)*IF($Z$3,100,1)) | J16: =IF(OR(Yeterlilik!$B23="",Yeterlilik!$C23=""),NA(),$Z$2*IF($Z$3,100,1)) | K16: =IF(OR(Yeterlilik!$B23="",Yeterlilik!$C23=""),NA(),C16/B16*IF($Z$3,100,1))
A17: =IF(OR(Yeterlilik!$B24="",Yeterlilik!$C24=""),NA(),16) | B17: =IF(OR(Yeterlilik!$B24="",Yeterlilik!$C24=""),NA(),Yeterlilik!$B24) | C17: =IF(OR(Yeterlilik!$B24="",Yeterlilik!$C24=""),NA(),Yeterlilik!$C24) | D17: =IF(OR(Yeterlilik!$B24="",Yeterlilik!$C24=""),NA(),CHOOSE($Z$1,C17/B17*100,C17,C17/B17,C17)) | E17: =IF(OR(Yeterlilik!$B24="",Yeterlilik!$C24=""),NA(),CHOOSE($Z$1,$Z$2*100,B17*$Z$2,$Z$2,B17*$Z$2)) | F17: =IF(OR(Yeterlilik!$B24="",Yeterlilik!$C24=""),NA(),CHOOSE($Z$1,SQRT($Z$2*(1-$Z$2)/B17)*100,SQRT(B17*$Z$2*(1-$Z$2)),SQRT($Z$2/B17),SQRT(B17*$Z$2))) | G17: =IF(OR(Yeterlilik!$B24="",Yeterlilik!$C24=""),NA(),E17+3*F17) | H17: =IF(OR(Yeterlilik!$B24="",Yeterlilik!$C24=""),NA(),MAX(0,E17-3*F17)) | I17: =IF(OR(Yeterlilik!$B24="",Yeterlilik!$C24=""),NA(),SUM(Yeterlilik!$C$9:$C24)/SUM(Yeterlilik!$B$9:$B24)*IF($Z$3,100,1)) | J17: =IF(OR(Yeterlilik!$B24="",Yeterlilik!$C24=""),NA(),$Z$2*IF($Z$3,100,1)) | K17: =IF(OR(Yeterlilik!$B24="",Yeterlilik!$C24=""),NA(),C17/B17*IF($Z$3,100,1))
A18: =IF(OR(Yeterlilik!$B25="",Yeterlilik!$C25=""),NA(),17) | B18: =IF(OR(Yeterlilik!$B25="",Yeterlilik!$C25=""),NA(),Yeterlilik!$B25) | C18: =IF(OR(Yeterlilik!$B25="",Yeterlilik!$C25=""),NA(),Yeterlilik!$C25) | D18: =IF(OR(Yeterlilik!$B25="",Yeterlilik!$C25=""),NA(),CHOOSE($Z$1,C18/B18*100,C18,C18/B18,C18)) | E18: =IF(OR(Yeterlilik!$B25="",Yeterlilik!$C25=""),NA(),CHOOSE($Z$1,$Z$2*100,B18*$Z$2,$Z$2,B18*$Z$2)) | F18: =IF(OR(Yeterlilik!$B25="",Yeterlilik!$C25=""),NA(),CHOOSE($Z$1,SQRT($Z$2*(1-$Z$2)/B18)*100,SQRT(B18*$Z$2*(1-$Z$2)),SQRT($Z$2/B18),SQRT(B18*$Z$2))) | G18: =IF(OR(Yeterlilik!$B25="",Yeterlilik!$C25=""),NA(),E18+3*F18) | H18: =IF(OR(Yeterlilik!$B25="",Yeterlilik!$C25=""),NA(),MAX(0,E18-3*F18)) | I18: =IF(OR(Yeterlilik!$B25="",Yeterlilik!$C25=""),NA(),SUM(Yeterlilik!$C$9:$C25)/SUM(Yeterlilik!$B$9:$B25)*IF($Z$3,100,1)) | J18: =IF(OR(Yeterlilik!$B25="",Yeterlilik!$C25=""),NA(),$Z$2*IF($Z$3,100,1)) | K18: =IF(OR(Yeterlilik!$B25="",Yeterlilik!$C25=""),NA(),C18/B18*IF($Z$3,100,1))
A19: =IF(OR(Yeterlilik!$B26="",Yeterlilik!$C26=""),NA(),18) | B19: =IF(OR(Yeterlilik!$B26="",Yeterlilik!$C26=""),NA(),Yeterlilik!$B26) | C19: =IF(OR(Yeterlilik!$B26="",Yeterlilik!$C26=""),NA(),Yeterlilik!$C26) | D19: =IF(OR(Yeterlilik!$B26="",Yeterlilik!$C26=""),NA(),CHOOSE($Z$1,C19/B19*100,C19,C19/B19,C19)) | E19: =IF(OR(Yeterlilik!$B26="",Yeterlilik!$C26=""),NA(),CHOOSE($Z$1,$Z$2*100,B19*$Z$2,$Z$2,B19*$Z$2)) | F19: =IF(OR(Yeterlilik!$B26="",Yeterlilik!$C26=""),NA(),CHOOSE($Z$1,SQRT($Z$2*(1-$Z$2)/B19)*100,SQRT(B19*$Z$2*(1-$Z$2)),SQRT($Z$2/B19),SQRT(B19*$Z$2))) | G19: =IF(OR(Yeterlilik!$B26="",Yeterlilik!$C26=""),NA(),E19+3*F19) | H19: =IF(OR(Yeterlilik!$B26="",Yeterlilik!$C26=""),NA(),MAX(0,E19-3*F19)) | I19: =IF(OR(Yeterlilik!$B26="",Yeterlilik!$C26=""),NA(),SUM(Yeterlilik!$C$9:$C26)/SUM(Yeterlilik!$B$9:$B26)*IF($Z$3,100,1)) | J19: =IF(OR(Yeterlilik!$B26="",Yeterlilik!$C26=""),NA(),$Z$2*IF($Z$3,100,1)) | K19: =IF(OR(Yeterlilik!$B26="",Yeterlilik!$C26=""),NA(),C19/B19*IF($Z$3,100,1))
A20: =IF(OR(Yeterlilik!$B27="",Yeterlilik!$C27=""),NA(),19) | B20: =IF(OR(Yeterlilik!$B27="",Yeterlilik!$C27=""),NA(),Yeterlilik!$B27) | C20: =IF(OR(Yeterlilik!$B27="",Yeterlilik!$C27=""),NA(),Yeterlilik!$C27) | D20: =IF(OR(Yeterlilik!$B27="",Yeterlilik!$C27=""),NA(),CHOOSE($Z$1,C20/B20*100,C20,C20/B20,C20)) | E20: =IF(OR(Yeterlilik!$B27="",Yeterlilik!$C27=""),NA(),CHOOSE($Z$1,$Z$2*100,B20*$Z$2,$Z$2,B20*$Z$2)) | F20: =IF(OR(Yeterlilik!$B27="",Yeterlilik!$C27=""),NA(),CHOOSE($Z$1,SQRT($Z$2*(1-$Z$2)/B20)*100,SQRT(B20*$Z$2*(1-$Z$2)),SQRT($Z$2/B20),SQRT(B20*$Z$2))) | G20: =IF(OR(Yeterlilik!$B27="",Yeterlilik!$C27=""),NA(),E20+3*F20) | H20: =IF(OR(Yeterlilik!$B27="",Yeterlilik!$C27=""),NA(),MAX(0,E20-3*F20)) | I20: =IF(OR(Yeterlilik!$B27="",Yeterlilik!$C27=""),NA(),SUM(Yeterlilik!$C$9:$C27)/SUM(Yeterlilik!$B$9:$B27)*IF($Z$3,100,1)) | J20: =IF(OR(Yeterlilik!$B27="",Yeterlilik!$C27=""),NA(),$Z$2*IF($Z$3,100,1)) | K20: =IF(OR(Yeterlilik!$B27="",Yeterlilik!$C27=""),NA(),C20/B20*IF($Z$3,100,1))
A21: =IF(OR(Yeterlilik!$B28="",Yeterlilik!$C28=""),NA(),20) | B21: =IF(OR(Yeterlilik!$B28="",Yeterlilik!$C28=""),NA(),Yeterlilik!$B28) | C21: =IF(OR(Yeterlilik!$B28="",Yeterlilik!$C28=""),NA(),Yeterlilik!$C28) | D21: =IF(OR(Yeterlilik!$B28="",Yeterlilik!$C28=""),NA(),CHOOSE($Z$1,C21/B21*100,C21,C21/B21,C21)) | E21: =IF(OR(Yeterlilik!$B28="",Yeterlilik!$C28=""),NA(),CHOOSE($Z$1,$Z$2*100,B21*$Z$2,$Z$2,B21*$Z$2)) | F21: =IF(OR(Yeterlilik!$B28="",Yeterlilik!$C28=""),NA(),CHOOSE($Z$1,SQRT($Z$2*(1-$Z$2)/B21)*100,SQRT(B21*$Z$2*(1-$Z$2)),SQRT($Z$2/B21),SQRT(B21*$Z$2))) | G21: =IF(OR(Yeterlilik!$B28="",Yeterlilik!$C28=""),NA(),E21+3*F21) | H21: =IF(OR(Yeterlilik!$B28="",Yeterlilik!$C28=""),NA(),MAX(0,E21-3*F21)) | I21: =IF(OR(Yeterlilik!$B28="",Yeterlilik!$C28=""),NA(),SUM(Yeterlilik!$C$9:$C28)/SUM(Yeterlilik!$B$9:$B28)*IF($Z$3,100,1)) | J21: =IF(OR(Yeterlilik!$B28="",Yeterlilik!$C28=""),NA(),$Z$2*IF($Z$3,100,1)) | K21: =IF(OR(Yeterlilik!$B28="",Yeterlilik!$C28=""),NA(),C21/B21*IF($Z$3,100,1))
A22: =IF(OR(Yeterlilik!$B29="",Yeterlilik!$C29=""),NA(),21) | B22: =IF(OR(Yeterlilik!$B29="",Yeterlilik!$C29=""),NA(),Yeterlilik!$B29) | C22: =IF(OR(Yeterlilik!$B29="",Yeterlilik!$C29=""),NA(),Yeterlilik!$C29) | D22: =IF(OR(Yeterlilik!$B29="",Yeterlilik!$C29=""),NA(),CHOOSE($Z$1,C22/B22*100,C22,C22/B22,C22)) | E22: =IF(OR(Yeterlilik!$B29="",Yeterlilik!$C29=""),NA(),CHOOSE($Z$1,$Z$2*100,B22*$Z$2,$Z$2,B22*$Z$2)) | F22: =IF(OR(Yeterlilik!$B29="",Yeterlilik!$C29=""),NA(),CHOOSE($Z$1,SQRT($Z$2*(1-$Z$2)/B22)*100,SQRT(B22*$Z$2*(1-$Z$2)),SQRT($Z$2/B22),SQRT(B22*$Z$2))) | G22: =IF(OR(Yeterlilik!$B29="",Yeterlilik!$C29=""),NA(),E22+3*F22) | H22: =IF(OR(Yeterlilik!$B29="",Yeterlilik!$C29=""),NA(),MAX(0,E22-3*F22)) | I22: =IF(OR(Yeterlilik!$B29="",Yeterlilik!$C29=""),NA(),SUM(Yeterlilik!$C$9:$C29)/SUM(Yeterlilik!$B$9:$B29)*IF($Z$3,100,1)) | J22: =IF(OR(Yeterlilik!$B29="",Yeterlilik!$C29=""),NA(),$Z$2*IF($Z$3,100,1)) | K22: =IF(OR(Yeterlilik!$B29="",Yeterlilik!$C29=""),NA(),C22/B22*IF($Z$3,100,1))
A23: =IF(OR(Yeterlilik!$B30="",Yeterlilik!$C30=""),NA(),22) | B23: =IF(OR(Yeterlilik!$B30="",Yeterlilik!$C30=""),NA(),Yeterlilik!$B30) | C23: =IF(OR(Yeterlilik!$B30="",Yeterlilik!$C30=""),NA(),Yeterlilik!$C30) | D23: =IF(OR(Yeterlilik!$B30="",Yeterlilik!$C30=""),NA(),CHOOSE($Z$1,C23/B23*100,C23,C23/B23,C23)) | E23: =IF(OR(Yeterlilik!$B30="",Yeterlilik!$C30=""),NA(),CHOOSE($Z$1,$Z$2*100,B23*$Z$2,$Z$2,B23*$Z$2)) | F23: =IF(OR(Yeterlilik!$B30="",Yeterlilik!$C30=""),NA(),CHOOSE($Z$1,SQRT($Z$2*(1-$Z$2)/B23)*100,SQRT(B23*$Z$2*(1-$Z$2)),SQRT($Z$2/B23),SQRT(B23*$Z$2))) | G23: =IF(OR(Yeterlilik!$B30="",Yeterlilik!$C30=""),NA(),E23+3*F23) | H23: =IF(OR(Yeterlilik!$B30="",Yeterlilik!$C30=""),NA(),MAX(0,E23-3*F23)) | I23: =IF(OR(Yeterlilik!$B30="",Yeterlilik!$C30=""),NA(),SUM(Yeterlilik!$C$9:$C30)/SUM(Yeterlilik!$B$9:$B30)*IF($Z$3,100,1)) | J23: =IF(OR(Yeterlilik!$B30="",Yeterlilik!$C30=""),NA(),$Z$2*IF($Z$3,100,1)) | K23: =IF(OR(Yeterlilik!$B30="",Yeterlilik!$C30=""),NA(),C23/B23*IF($Z$3,100,1))
A24: =IF(OR(Yeterlilik!$B31="",Yeterlilik!$C31=""),NA(),23) | B24: =IF(OR(Yeterlilik!$B31="",Yeterlilik!$C31=""),NA(),Yeterlilik!$B31) | C24: =IF(OR(Yeterlilik!$B31="",Yeterlilik!$C31=""),NA(),Yeterlilik!$C31) | D24: =IF(OR(Yeterlilik!$B31="",Yeterlilik!$C31=""),NA(),CHOOSE($Z$1,C24/B24*100,C24,C24/B24,C24)) | E24: =IF(OR(Yeterlilik!$B31="",Yeterlilik!$C31=""),NA(),CHOOSE($Z$1,$Z$2*100,B24*$Z$2,$Z$2,B24*$Z$2)) | F24: =IF(OR(Yeterlilik!$B31="",Yeterlilik!$C31=""),NA(),CHOOSE($Z$1,SQRT($Z$2*(1-$Z$2)/B24)*100,SQRT(B24*$Z$2*(1-$Z$2)),SQRT($Z$2/B24),SQRT(B24*$Z$2))) | G24: =IF(OR(Yeterlilik!$B31="",Yeterlilik!$C31=""),NA(),E24+3*F24) | H24: =IF(OR(Yeterlilik!$B31="",Yeterlilik!$C31=""),NA(),MAX(0,E24-3*F24)) | I24: =IF(OR(Yeterlilik!$B31="",Yeterlilik!$C31=""),NA(),SUM(Yeterlilik!$C$9:$C31)/SUM(Yeterlilik!$B$9:$B31)*IF($Z$3,100,1)) | J24: =IF(OR(Yeterlilik!$B31="",Yeterlilik!$C31=""),NA(),$Z$2*IF($Z$3,100,1)) | K24: =IF(OR(Yeterlilik!$B31="",Yeterlilik!$C31=""),NA(),C24/B24*IF($Z$3,100,1))
A25: =IF(OR(Yeterlilik!$B32="",Yeterlilik!$C32=""),NA(),24) | B25: =IF(OR(Yeterlilik!$B32="",Yeterlilik!$C32=""),NA(),Yeterlilik!$B32) | C25: =IF(OR(Yeterlilik!$B32="",Yeterlilik!$C32=""),NA(),Yeterlilik!$C32) | D25: =IF(OR(Yeterlilik!$B32="",Yeterlilik!$C32=""),NA(),CHOOSE($Z$1,C25/B25*100,C25,C25/B25,C25)) | E25: =IF(OR(Yeterlilik!$B32="",Yeterlilik!$C32=""),NA(),CHOOSE($Z$1,$Z$2*100,B25*$Z$2,$Z$2,B25*$Z$2)) | F25: =IF(OR(Yeterlilik!$B32="",Yeterlilik!$C32=""),NA(),CHOOSE($Z$1,SQRT($Z$2*(1-$Z$2)/B25)*100,SQRT(B25*$Z$2*(1-$Z$2)),SQRT($Z$2/B25),SQRT(B25*$Z$2))) | G25: =IF(OR(Yeterlilik!$B32="",Yeterlilik!$C32=""),NA(),E25+3*F25) | H25: =IF(OR(Yeterlilik!$B32="",Yeterlilik!$C32=""),NA(),MAX(0,E25-3*F25)) | I25: =IF(OR(Yeterlilik!$B32="",Yeterlilik!$C32=""),NA(),SUM(Yeterlilik!$C$9:$C32)/SUM(Yeterlilik!$B$9:$B32)*IF($Z$3,100,1)) | J25: =IF(OR(Yeterlilik!$B32="",Yeterlilik!$C32=""),NA(),$Z$2*IF($Z$3,100,1)) | K25: =IF(OR(Yeterlilik!$B32="",Yeterlilik!$C32=""),NA(),C25/B25*IF($Z$3,100,1))
A26: =IF(OR(Yeterlilik!$B33="",Yeterlilik!$C33=""),NA(),25) | B26: =IF(OR(Yeterlilik!$B33="",Yeterlilik!$C33=""),NA(),Yeterlilik!$B33) | C26: =IF(OR(Yeterlilik!$B33="",Yeterlilik!$C33=""),NA(),Yeterlilik!$C33) | D26: =IF(OR(Yeterlilik!$B33="",Yeterlilik!$C33=""),NA(),CHOOSE($Z$1,C26/B26*100,C26,C26/B26,C26)) | E26: =IF(OR(Yeterlilik!$B33="",Yeterlilik!$C33=""),NA(),CHOOSE($Z$1,$Z$2*100,B26*$Z$2,$Z$2,B26*$Z$2)) | F26: =IF(OR(Yeterlilik!$B33="",Yeterlilik!$C33=""),NA(),CHOOSE($Z$1,SQRT($Z$2*(1-$Z$2)/B26)*100,SQRT(B26*$Z$2*(1-$Z$2)),SQRT($Z$2/B26),SQRT(B26*$Z$2))) | G26: =IF(OR(Yeterlilik!$B33="",Yeterlilik!$C33=""),NA(),E26+3*F26) | H26: =IF(OR(Yeterlilik!$B33="",Yeterlilik!$C33=""),NA(),MAX(0,E26-3*F26)) | I26: =IF(OR(Yeterlilik!$B33="",Yeterlilik!$C33=""),NA(),SUM(Yeterlilik!$C$9:$C33)/SUM(Yeterlilik!$B$9:$B33)*IF($Z$3,100,1)) | J26: =IF(OR(Yeterlilik!$B33="",Yeterlilik!$C33=""),NA(),$Z$2*IF($Z$3,100,1)) | K26: =IF(OR(Yeterlilik!$B33="",Yeterlilik!$C33=""),NA(),C26/B26*IF($Z$3,100,1))
A27: =IF(OR(Yeterlilik!$B34="",Yeterlilik!$C34=""),NA(),26) | B27: =IF(OR(Yeterlilik!$B34="",Yeterlilik!$C34=""),NA(),Yeterlilik!$B34) | C27: =IF(OR(Yeterlilik!$B34="",Yeterlilik!$C34=""),NA(),Yeterlilik!$C34) | D27: =IF(OR(Yeterlilik!$B34="",Yeterlilik!$C34=""),NA(),CHOOSE($Z$1,C27/B27*100,C27,C27/B27,C27)) | E27: =IF(OR(Yeterlilik!$B34="",Yeterlilik!$C34=""),NA(),CHOOSE($Z$1,$Z$2*100,B27*$Z$2,$Z$2,B27*$Z$2)) | F27: =IF(OR(Yeterlilik!$B34="",Yeterlilik!$C34=""),NA(),CHOOSE($Z$1,SQRT($Z$2*(1-$Z$2)/B27)*100,SQRT(B27*$Z$2*(1-$Z$2)),SQRT($Z$2/B27),SQRT(B27*$Z$2))) | G27: =IF(OR(Yeterlilik!$B34="",Yeterlilik!$C34=""),NA(),E27+3*F27) | H27: =IF(OR(Yeterlilik!$B34="",Yeterlilik!$C34=""),NA(),MAX(0,E27-3*F27)) | I27: =IF(OR(Yeterlilik!$B34="",Yeterlilik!$C34=""),NA(),SUM(Yeterlilik!$C$9:$C34)/SUM(Yeterlilik!$B$9:$B34)*IF($Z$3,100,1)) | J27: =IF(OR(Yeterlilik!$B34="",Yeterlilik!$C34=""),NA(),$Z$2*IF($Z$3,100,1)) | K27: =IF(OR(Yeterlilik!$B34="",Yeterlilik!$C34=""),NA(),C27/B27*IF($Z$3,100,1))
A28: =IF(OR(Yeterlilik!$B35="",Yeterlilik!$C35=""),NA(),27) | B28: =IF(OR(Yeterlilik!$B35="",Yeterlilik!$C35=""),NA(),Yeterlilik!$B35) | C28: =IF(OR(Yeterlilik!$B35="",Yeterlilik!$C35=""),NA(),Yeterlilik!$C35) | D28: =IF(OR(Yeterlilik!$B35="",Yeterlilik!$C35=""),NA(),CHOOSE($Z$1,C28/B28*100,C28,C28/B28,C28)) | E28: =IF(OR(Yeterlilik!$B35="",Yeterlilik!$C35=""),NA(),CHOOSE($Z$1,$Z$2*100,B28*$Z$2,$Z$2,B28*$Z$2)) | F28: =IF(OR(Yeterlilik!$B35="",Yeterlilik!$C35=""),NA(),CHOOSE($Z$1,SQRT($Z$2*(1-$Z$2)/B28)*100,SQRT(B28*$Z$2*(1-$Z$2)),SQRT($Z$2/B28),SQRT(B28*$Z$2))) | G28: =IF(OR(Yeterlilik!$B35="",Yeterlilik!$C35=""),NA(),E28+3*F28) | H28: =IF(OR(Yeterlilik!$B35="",Yeterlilik!$C35=""),NA(),MAX(0,E28-3*F28)) | I28: =IF(OR(Yeterlilik!$B35="",Yeterlilik!$C35=""),NA(),SUM(Yeterlilik!$C$9:$C35)/SUM(Yeterlilik!$B$9:$B35)*IF($Z$3,100,1)) | J28: =IF(OR(Yeterlilik!$B35="",Yeterlilik!$C35=""),NA(),$Z$2*IF($Z$3,100,1)) | K28: =IF(OR(Yeterlilik!$B35="",Yeterlilik!$C35=""),NA(),C28/B28*IF($Z$3,100,1))
A29: =IF(OR(Yeterlilik!$B36="",Yeterlilik!$C36=""),NA(),28) | B29: =IF(OR(Yeterlilik!$B36="",Yeterlilik!$C36=""),NA(),Yeterlilik!$B36) | C29: =IF(OR(Yeterlilik!$B36="",Yeterlilik!$C36=""),NA(),Yeterlilik!$C36) | D29: =IF(OR(Yeterlilik!$B36="",Yeterlilik!$C36=""),NA(),CHOOSE($Z$1,C29/B29*100,C29,C29/B29,C29)) | E29: =IF(OR(Yeterlilik!$B36="",Yeterlilik!$C36=""),NA(),CHOOSE($Z$1,$Z$2*100,B29*$Z$2,$Z$2,B29*$Z$2)) | F29: =IF(OR(Yeterlilik!$B36="",Yeterlilik!$C36=""),NA(),CHOOSE($Z$1,SQRT($Z$2*(1-$Z$2)/B29)*100,SQRT(B29*$Z$2*(1-$Z$2)),SQRT($Z$2/B29),SQRT(B29*$Z$2))) | G29: =IF(OR(Yeterlilik!$B36="",Yeterlilik!$C36=""),NA(),E29+3*F29) | H29: =IF(OR(Yeterlilik!$B36="",Yeterlilik!$C36=""),NA(),MAX(0,E29-3*F29)) | I29: =IF(OR(Yeterlilik!$B36="",Yeterlilik!$C36=""),NA(),SUM(Yeterlilik!$C$9:$C36)/SUM(Yeterlilik!$B$9:$B36)*IF($Z$3,100,1)) | J29: =IF(OR(Yeterlilik!$B36="",Yeterlilik!$C36=""),NA(),$Z$2*IF($Z$3,100,1)) | K29: =IF(OR(Yeterlilik!$B36="",Yeterlilik!$C36=""),NA(),C29/B29*IF($Z$3,100,1))
A30: =IF(OR(Yeterlilik!$B37="",Yeterlilik!$C37=""),NA(),29) | B30: =IF(OR(Yeterlilik!$B37="",Yeterlilik!$C37=""),NA(),Yeterlilik!$B37) | C30: =IF(OR(Yeterlilik!$B37="",Yeterlilik!$C37=""),NA(),Yeterlilik!$C37) | D30: =IF(OR(Yeterlilik!$B37="",Yeterlilik!$C37=""),NA(),CHOOSE($Z$1,C30/B30*100,C30,C30/B30,C30)) | E30: =IF(OR(Yeterlilik!$B37="",Yeterlilik!$C37=""),NA(),CHOOSE($Z$1,$Z$2*100,B30*$Z$2,$Z$2,B30*$Z$2)) | F30: =IF(OR(Yeterlilik!$B37="",Yeterlilik!$C37=""),NA(),CHOOSE($Z$1,SQRT($Z$2*(1-$Z$2)/B30)*100,SQRT(B30*$Z$2*(1-$Z$2)),SQRT($Z$2/B30),SQRT(B30*$Z$2))) | G30: =IF(OR(Yeterlilik!$B37="",Yeterlilik!$C37=""),NA(),E30+3*F30) | H30: =IF(OR(Yeterlilik!$B37="",Yeterlilik!$C37=""),NA(),MAX(0,E30-3*F30)) | I30: =IF(OR(Yeterlilik!$B37="",Yeterlilik!$C37=""),NA(),SUM(Yeterlilik!$C$9:$C37)/SUM(Yeterlilik!$B$9:$B37)*IF($Z$3,100,1)) | J30: =IF(OR(Yeterlilik!$B37="",Yeterlilik!$C37=""),NA(),$Z$2*IF($Z$3,100,1)) | K30: =IF(OR(Yeterlilik!$B37="",Yeterlilik!$C37=""),NA(),C30/B30*IF($Z$3,100,1))
A31: =IF(OR(Yeterlilik!$B38="",Yeterlilik!$C38=""),NA(),30) | B31: =IF(OR(Yeterlilik!$B38="",Yeterlilik!$C38=""),NA(),Yeterlilik!$B38) | C31: =IF(OR(Yeterlilik!$B38="",Yeterlilik!$C38=""),NA(),Yeterlilik!$C38) | D31: =IF(OR(Yeterlilik!$B38="",Yeterlilik!$C38=""),NA(),CHOOSE($Z$1,C31/B31*100,C31,C31/B31,C31)) | E31: =IF(OR(Yeterlilik!$B38="",Yeterlilik!$C38=""),NA(),CHOOSE($Z$1,$Z$2*100,B31*$Z$2,$Z$2,B31*$Z$2)) | F31: =IF(OR(Yeterlilik!$B38="",Yeterlilik!$C38=""),NA(),CHOOSE($Z$1,SQRT($Z$2*(1-$Z$2)/B31)*100,SQRT(B31*$Z$2*(1-$Z$2)),SQRT($Z$2/B31),SQRT(B31*$Z$2))) | G31: =IF(OR(Yeterlilik!$B38="",Yeterlilik!$C38=""),NA(),E31+3*F31) | H31: =IF(OR(Yeterlilik!$B38="",Yeterlilik!$C38=""),NA(),MAX(0,E31-3*F31)) | I31: =IF(OR(Yeterlilik!$B38="",Yeterlilik!$C38=""),NA(),SUM(Yeterlilik!$C$9:$C38)/SUM(Yeterlilik!$B$9:$B38)*IF($Z$3,100,1)) | J31: =IF(OR(Yeterlilik!$B38="",Yeterlilik!$C38=""),NA(),$Z$2*IF($Z$3,100,1)) | K31: =IF(OR(Yeterlilik!$B38="",Yeterlilik!$C38=""),NA(),C31/B31*IF($Z$3,100,1))
A32: =IF(OR(Yeterlilik!$B39="",Yeterlilik!$C39=""),NA(),31) | B32: =IF(OR(Yeterlilik!$B39="",Yeterlilik!$C39=""),NA(),Yeterlilik!$B39) | C32: =IF(OR(Yeterlilik!$B39="",Yeterlilik!$C39=""),NA(),Yeterlilik!$C39) | D32: =IF(OR(Yeterlilik!$B39="",Yeterlilik!$C39=""),NA(),CHOOSE($Z$1,C32/B32*100,C32,C32/B32,C32)) | E32: =IF(OR(Yeterlilik!$B39="",Yeterlilik!$C39=""),NA(),CHOOSE($Z$1,$Z$2*100,B32*$Z$2,$Z$2,B32*$Z$2)) | F32: =IF(OR(Yeterlilik!$B39="",Yeterlilik!$C39=""),NA(),CHOOSE($Z$1,SQRT($Z$2*(1-$Z$2)/B32)*100,SQRT(B32*$Z$2*(1-$Z$2)),SQRT($Z$2/B32),SQRT(B32*$Z$2))) | G32: =IF(OR(Yeterlilik!$B39="",Yeterlilik!$C39=""),NA(),E32+3*F32) | H32: =IF(OR(Yeterlilik!$B39="",Yeterlilik!$C39=""),NA(),MAX(0,E32-3*F32)) | I32: =IF(OR(Yeterlilik!$B39="",Yeterlilik!$C39=""),NA(),SUM(Yeterlilik!$C$9:$C39)/SUM(Yeterlilik!$B$9:$B39)*IF($Z$3,100,1)) | J32: =IF(OR(Yeterlilik!$B39="",Yeterlilik!$C39=""),NA(),$Z$2*IF($Z$3,100,1)) | K32: =IF(OR(Yeterlilik!$B39="",Yeterlilik!$C39=""),NA(),C32/B32*IF($Z$3,100,1))
A33: =IF(OR(Yeterlilik!$B40="",Yeterlilik!$C40=""),NA(),32) | B33: =IF(OR(Yeterlilik!$B40="",Yeterlilik!$C40=""),NA(),Yeterlilik!$B40) | C33: =IF(OR(Yeterlilik!$B40="",Yeterlilik!$C40=""),NA(),Yeterlilik!$C40) | D33: =IF(OR(Yeterlilik!$B40="",Yeterlilik!$C40=""),NA(),CHOOSE($Z$1,C33/B33*100,C33,C33/B33,C33)) | E33: =IF(OR(Yeterlilik!$B40="",Yeterlilik!$C40=""),NA(),CHOOSE($Z$1,$Z$2*100,B33*$Z$2,$Z$2,B33*$Z$2)) | F33: =IF(OR(Yeterlilik!$B40="",Yeterlilik!$C40=""),NA(),CHOOSE($Z$1,SQRT($Z$2*(1-$Z$2)/B33)*100,SQRT(B33*$Z$2*(1-$Z$2)),SQRT($Z$2/B33),SQRT(B33*$Z$2))) | G33: =IF(OR(Yeterlilik!$B40="",Yeterlilik!$C40=""),NA(),E33+3*F33) | H33: =IF(OR(Yeterlilik!$B40="",Yeterlilik!$C40=""),NA(),MAX(0,E33-3*F33)) | I33: =IF(OR(Yeterlilik!$B40="",Yeterlilik!$C40=""),NA(),SUM(Yeterlilik!$C$9:$C40)/SUM(Yeterlilik!$B$9:$B40)*IF($Z$3,100,1)) | J33: =IF(OR(Yeterlilik!$B40="",Yeterlilik!$C40=""),NA(),$Z$2*IF($Z$3,100,1)) | K33: =IF(OR(Yeterlilik!$B40="",Yeterlilik!$C40=""),NA(),C33/B33*IF($Z$3,100,1))
A34: =IF(OR(Yeterlilik!$B41="",Yeterlilik!$C41=""),NA(),33) | B34: =IF(OR(Yeterlilik!$B41="",Yeterlilik!$C41=""),NA(),Yeterlilik!$B41) | C34: =IF(OR(Yeterlilik!$B41="",Yeterlilik!$C41=""),NA(),Yeterlilik!$C41) | D34: =IF(OR(Yeterlilik!$B41="",Yeterlilik!$C41=""),NA(),CHOOSE($Z$1,C34/B34*100,C34,C34/B34,C34)) | E34: =IF(OR(Yeterlilik!$B41="",Yeterlilik!$C41=""),NA(),CHOOSE($Z$1,$Z$2*100,B34*$Z$2,$Z$2,B34*$Z$2)) | F34: =IF(OR(Yeterlilik!$B41="",Yeterlilik!$C41=""),NA(),CHOOSE($Z$1,SQRT($Z$2*(1-$Z$2)/B34)*100,SQRT(B34*$Z$2*(1-$Z$2)),SQRT($Z$2/B34),SQRT(B34*$Z$2))) | G34: =IF(OR(Yeterlilik!$B41="",Yeterlilik!$C41=""),NA(),E34+3*F34) | H34: =IF(OR(Yeterlilik!$B41="",Yeterlilik!$C41=""),NA(),MAX(0,E34-3*F34)) | I34: =IF(OR(Yeterlilik!$B41="",Yeterlilik!$C41=""),NA(),SUM(Yeterlilik!$C$9:$C41)/SUM(Yeterlilik!$B$9:$B41)*IF($Z$3,100,1)) | J34: =IF(OR(Yeterlilik!$B41="",Yeterlilik!$C41=""),NA(),$Z$2*IF($Z$3,100,1)) | K34: =IF(OR(Yeterlilik!$B41="",Yeterlilik!$C41=""),NA(),C34/B34*IF($Z$3,100,1))
A35: =IF(OR(Yeterlilik!$B42="",Yeterlilik!$C42=""),NA(),34) | B35: =IF(OR(Yeterlilik!$B42="",Yeterlilik!$C42=""),NA(),Yeterlilik!$B42) | C35: =IF(OR(Yeterlilik!$B42="",Yeterlilik!$C42=""),NA(),Yeterlilik!$C42) | D35: =IF(OR(Yeterlilik!$B42="",Yeterlilik!$C42=""),NA(),CHOOSE($Z$1,C35/B35*100,C35,C35/B35,C35)) | E35: =IF(OR(Yeterlilik!$B42="",Yeterlilik!$C42=""),NA(),CHOOSE($Z$1,$Z$2*100,B35*$Z$2,$Z$2,B35*$Z$2)) | F35: =IF(OR(Yeterlilik!$B42="",Yeterlilik!$C42=""),NA(),CHOOSE($Z$1,SQRT($Z$2*(1-$Z$2)/B35)*100,SQRT(B35*$Z$2*(1-$Z$2)),SQRT($Z$2/B35),SQRT(B35*$Z$2))) | G35: =IF(OR(Yeterlilik!$B42="",Yeterlilik!$C42=""),NA(),E35+3*F35) | H35: =IF(OR(Yeterlilik!$B42="",Yeterlilik!$C42=""),NA(),MAX(0,E35-3*F35)) | I35: =IF(OR(Yeterlilik!$B42="",Yeterlilik!$C42=""),NA(),SUM(Yeterlilik!$C$9:$C42)/SUM(Yeterlilik!$B$9:$B42)*IF($Z$3,100,1)) | J35: =IF(OR(Yeterlilik!$B42="",Yeterlilik!$C42=""),NA(),$Z$2*IF($Z$3,100,1)) | K35: =IF(OR(Yeterlilik!$B42="",Yeterlilik!$C42=""),NA(),C35/B35*IF($Z$3,100,1))
A36: =IF(OR(Yeterlilik!$B43="",Yeterlilik!$C43=""),NA(),35) | B36: =IF(OR(Yeterlilik!$B43="",Yeterlilik!$C43=""),NA(),Yeterlilik!$B43) | C36: =IF(OR(Yeterlilik!$B43="",Yeterlilik!$C43=""),NA(),Yeterlilik!$C43) | D36: =IF(OR(Yeterlilik!$B43="",Yeterlilik!$C43=""),NA(),CHOOSE($Z$1,C36/B36*100,C36,C36/B36,C36)) | E36: =IF(OR(Yeterlilik!$B43="",Yeterlilik!$C43=""),NA(),CHOOSE($Z$1,$Z$2*100,B36*$Z$2,$Z$2,B36*$Z$2)) | F36: =IF(OR(Yeterlilik!$B43="",Yeterlilik!$C43=""),NA(),CHOOSE($Z$1,SQRT($Z$2*(1-$Z$2)/B36)*100,SQRT(B36*$Z$2*(1-$Z$2)),SQRT($Z$2/B36),SQRT(B36*$Z$2))) | G36: =IF(OR(Yeterlilik!$B43="",Yeterlilik!$C43=""),NA(),E36+3*F36) | H36: =IF(OR(Yeterlilik!$B43="",Yeterlilik!$C43=""),NA(),MAX(0,E36-3*F36)) | I36: =IF(OR(Yeterlilik!$B43="",Yeterlilik!$C43=""),NA(),SUM(Yeterlilik!$C$9:$C43)/SUM(Yeterlilik!$B$9:$B43)*IF($Z$3,100,1)) | J36: =IF(OR(Yeterlilik!$B43="",Yeterlilik!$C43=""),NA(),$Z$2*IF($Z$3,100,1)) | K36: =IF(OR(Yeterlilik!$B43="",Yeterlilik!$C43=""),NA(),C36/B36*IF($Z$3,100,1))
A37: =IF(OR(Yeterlilik!$B44="",Yeterlilik!$C44=""),NA(),36) | B37: =IF(OR(Yeterlilik!$B44="",Yeterlilik!$C44=""),NA(),Yeterlilik!$B44) | C37: =IF(OR(Yeterlilik!$B44="",Yeterlilik!$C44=""),NA(),Yeterlilik!$C44) | D37: =IF(OR(Yeterlilik!$B44="",Yeterlilik!$C44=""),NA(),CHOOSE($Z$1,C37/B37*100,C37,C37/B37,C37)) | E37: =IF(OR(Yeterlilik!$B44="",Yeterlilik!$C44=""),NA(),CHOOSE($Z$1,$Z$2*100,B37*$Z$2,$Z$2,B37*$Z$2)) | F37: =IF(OR(Yeterlilik!$B44="",Yeterlilik!$C44=""),NA(),CHOOSE($Z$1,SQRT($Z$2*(1-$Z$2)/B37)*100,SQRT(B37*$Z$2*(1-$Z$2)),SQRT($Z$2/B37),SQRT(B37*$Z$2))) | G37: =IF(OR(Yeterlilik!$B44="",Yeterlilik!$C44=""),NA(),E37+3*F37) | H37: =IF(OR(Yeterlilik!$B44="",Yeterlilik!$C44=""),NA(),MAX(0,E37-3*F37)) | I37: =IF(OR(Yeterlilik!$B44="",Yeterlilik!$C44=""),NA(),SUM(Yeterlilik!$C$9:$C44)/SUM(Yeterlilik!$B$9:$B44)*IF($Z$3,100,1)) | J37: =IF(OR(Yeterlilik!$B44="",Yeterlilik!$C44=""),NA(),$Z$2*IF($Z$3,100,1)) | K37: =IF(OR(Yeterlilik!$B44="",Yeterlilik!$C44=""),NA(),C37/B37*IF($Z$3,100,1))
A38: =IF(OR(Yeterlilik!$B45="",Yeterlilik!$C45=""),NA(),37) | B38: =IF(OR(Yeterlilik!$B45="",Yeterlilik!$C45=""),NA(),Yeterlilik!$B45) | C38: =IF(OR(Yeterlilik!$B45="",Yeterlilik!$C45=""),NA(),Yeterlilik!$C45) | D38: =IF(OR(Yeterlilik!$B45="",Yeterlilik!$C45=""),NA(),CHOOSE($Z$1,C38/B38*100,C38,C38/B38,C38)) | E38: =IF(OR(Yeterlilik!$B45="",Yeterlilik!$C45=""),NA(),CHOOSE($Z$1,$Z$2*100,B38*$Z$2,$Z$2,B38*$Z$2)) | F38: =IF(OR(Yeterlilik!$B45="",Yeterlilik!$C45=""),NA(),CHOOSE($Z$1,SQRT($Z$2*(1-$Z$2)/B38)*100,SQRT(B38*$Z$2*(1-$Z$2)),SQRT($Z$2/B38),SQRT(B38*$Z$2))) | G38: =IF(OR(Yeterlilik!$B45="",Yeterlilik!$C45=""),NA(),E38+3*F38) | H38: =IF(OR(Yeterlilik!$B45="",Yeterlilik!$C45=""),NA(),MAX(0,E38-3*F38)) | I38: =IF(OR(Yeterlilik!$B45="",Yeterlilik!$C45=""),NA(),SUM(Yeterlilik!$C$9:$C45)/SUM(Yeterlilik!$B$9:$B45)*IF($Z$3,100,1)) | J38: =IF(OR(Yeterlilik!$B45="",Yeterlilik!$C45=""),NA(),$Z$2*IF($Z$3,100,1)) | K38: =IF(OR(Yeterlilik!$B45="",Yeterlilik!$C45=""),NA(),C38/B38*IF($Z$3,100,1))
A39: =IF(OR(Yeterlilik!$B46="",Yeterlilik!$C46=""),NA(),38) | B39: =IF(OR(Yeterlilik!$B46="",Yeterlilik!$C46=""),NA(),Yeterlilik!$B46) | C39: =IF(OR(Yeterlilik!$B46="",Yeterlilik!$C46=""),NA(),Yeterlilik!$C46) | D39: =IF(OR(Yeterlilik!$B46="",Yeterlilik!$C46=""),NA(),CHOOSE($Z$1,C39/B39*100,C39,C39/B39,C39)) | E39: =IF(OR(Yeterlilik!$B46="",Yeterlilik!$C46=""),NA(),CHOOSE($Z$1,$Z$2*100,B39*$Z$2,$Z$2,B39*$Z$2)) | F39: =IF(OR(Yeterlilik!$B46="",Yeterlilik!$C46=""),NA(),CHOOSE($Z$1,SQRT($Z$2*(1-$Z$2)/B39)*100,SQRT(B39*$Z$2*(1-$Z$2)),SQRT($Z$2/B39),SQRT(B39*$Z$2))) | G39: =IF(OR(Yeterlilik!$B46="",Yeterlilik!$C46=""),NA(),E39+3*F39) | H39: =IF(OR(Yeterlilik!$B46="",Yeterlilik!$C46=""),NA(),MAX(0,E39-3*F39)) | I39: =IF(OR(Yeterlilik!$B46="",Yeterlilik!$C46=""),NA(),SUM(Yeterlilik!$C$9:$C46)/SUM(Yeterlilik!$B$9:$B46)*IF($Z$3,100,1)) | J39: =IF(OR(Yeterlilik!$B46="",Yeterlilik!$C46=""),NA(),$Z$2*IF($Z$3,100,1)) | K39: =IF(OR(Yeterlilik!$B46="",Yeterlilik!$C46=""),NA(),C39/B39*IF($Z$3,100,1))
A40: =IF(OR(Yeterlilik!$B47="",Yeterlilik!$C47=""),NA(),39) | B40: =IF(OR(Yeterlilik!$B47="",Yeterlilik!$C47=""),NA(),Yeterlilik!$B47) | C40: =IF(OR(Yeterlilik!$B47="",Yeterlilik!$C47=""),NA(),Yeterlilik!$C47) | D40: =IF(OR(Yeterlilik!$B47="",Yeterlilik!$C47=""),NA(),CHOOSE($Z$1,C40/B40*100,C40,C40/B40,C40)) | E40: =IF(OR(Yeterlilik!$B47="",Yeterlilik!$C47=""),NA(),CHOOSE($Z$1,$Z$2*100,B40*$Z$2,$Z$2,B40*$Z$2)) | F40: =IF(OR(Yeterlilik!$B47="",Yeterlilik!$C47=""),NA(),CHOOSE($Z$1,SQRT($Z$2*(1-$Z$2)/B40)*100,SQRT(B40*$Z$2*(1-$Z$2)),SQRT($Z$2/B40),SQRT(B40*$Z$2))) | G40: =IF(OR(Yeterlilik!$B47="",Yeterlilik!$C47=""),NA(),E40+3*F40) | H40: =IF(OR(Yeterlilik!$B47="",Yeterlilik!$C47=""),NA(),MAX(0,E40-3*F40)) | I40: =IF(OR(Yeterlilik!$B47="",Yeterlilik!$C47=""),NA(),SUM(Yeterlilik!$C$9:$C47)/SUM(Yeterlilik!$B$9:$B47)*IF($Z$3,100,1)) | J40: =IF(OR(Yeterlilik!$B47="",Yeterlilik!$C47=""),NA(),$Z$2*IF($Z$3,100,1)) | K40: =IF(OR(Yeterlilik!$B47="",Yeterlilik!$C47=""),NA(),C40/B40*IF($Z$3,100,1))
...
